2025-08-13 18:25:32,557 - INFO - Sensor read successful: Indoor=(22, 32, 33), Outdoor=(18, 29, 31)
2025-08-13 18:25:42,558 - INFO - Sensor read successful: Indoor=(22, 33, 34), Outdoor=(18, 29, 31)
2025-08-13 18:25:52,559 - INFO - Sensor read successful: Indoor=(23, 34, 35), Outdoor=(18, 29, 31)
2025-08-13 18:26:02,560 - INFO - Sensor read successful: Indoor=(23, 34, 35), Outdoor=(18, 30, 32)
2025-08-13 18:26:12,561 - INFO - Sensor read successful: Indoor=(24, 34, 36), Outdoor=(18, 30, 32)
2025-08-13 18:26:22,562 - INFO - Sensor read successful: Indoor=(24, 34, 36), Outdoor=(18, 30, 32)
2025-08-13 18:26:32,563 - INFO - Sensor read successful: Indoor=(24, 34, 36), Outdoor=(18, 32, 34)
2025-08-13 18:26:42,564 - INFO - Sensor read successful: Indoor=(24, 34, 37), Outdoor=(18, 32, 34)
2025-08-13 18:26:52,565 - INFO - Sensor read successful: Indoor=(24, 34, 37), Outdoor=(18, 32, 34)
2025-08-13 18:27:02,566 - INFO - Sensor read successful: Indoor=(24, 34, 37), Outdoor=(19, 33, 35)
2025-08-13 18:27:12,566 - INFO - Sensor read successful: Indoor=(25, 35, 38), Outdoor=(19, 33, 35)
2025-08-13 18:27:22,567 - INFO - Sensor read successful: Indoor=(25, 35, 38), Outdoor=(19, 33, 35)
2025-08-13 18:27:32,567 - INFO - Sensor read successful: Indoor=(25, 35, 38), Outdoor=(19, 34, 36)
2025-08-13 18:27:39,506 - INFO - Program stopped by user
2025-08-24 16:31:52,962 - WARNING - Missing or invalid sensor data: Indoor=(nan, nan, nan), Outdoor=(0, 0, 0)
2025-08-24 16:32:03,963 - WARNING - Missing or invalid sensor data: Indoor=(nan, nan, nan), Outdoor=(0, 0, 0)
2025-08-24 16:32:14,965 - WARNING - Missing or invalid sensor data: Indoor=(nan, nan, nan), Outdoor=(0, 0, 0)
2025-08-24 16:32:25,966 - WARNING - Missing or invalid sensor data: Indoor=(nan, nan, nan), Outdoor=(0, 0, 0)
2025-08-24 16:32:36,967 - WARNING - Missing or invalid sensor data: Indoor=(nan, nan, nan), Outdoor=(0, 0, 0)
2025-08-24 16:32:46,968 - INFO - Sensor read successful: Indoor=(5, 8, 12), Outdoor=(0, 0, 0)
2025-08-24 16:32:56,968 - INFO - Sensor read successful: Indoor=(5, 8, 12), Outdoor=(0, 0, 0)
2025-08-24 16:33:06,969 - INFO - Sensor read successful: Indoor=(4, 7, 11), Outdoor=(0, 0, 0)
2025-08-24 16:33:16,970 - INFO - Sensor read successful: Indoor=(4, 7, 11), Outdoor=(0, 0, 0)
2025-08-24 16:33:26,970 - INFO - Sensor read successful: Indoor=(4, 7, 11), Outdoor=(0, 0, 0)
2025-08-24 16:33:36,970 - INFO - Sensor read successful: Indoor=(5, 7, 11), Outdoor=(0, 0, 0)
2025-08-24 16:33:46,971 - INFO - Sensor read successful: Indoor=(5, 7, 11), Outdoor=(0, 0, 0)
2025-08-24 16:33:56,971 - INFO - Sensor read successful: Indoor=(5, 7, 11), Outdoor=(0, 0, 0)
2025-08-24 16:34:06,972 - INFO - Sensor read successful: Indoor=(4, 6, 10), Outdoor=(0, 0, 0)
2025-08-24 16:34:16,972 - INFO - Sensor read successful: Indoor=(4, 6, 10), Outdoor=(0, 0, 0)
2025-08-24 16:34:26,973 - INFO - Sensor read successful: Indoor=(4, 6, 10), Outdoor=(0, 0, 0)
2025-08-24 16:34:36,973 - INFO - Sensor read successful: Indoor=(3, 5, 9), Outdoor=(0, 0, 0)
2025-08-24 16:34:46,974 - INFO - Sensor read successful: Indoor=(3, 5, 9), Outdoor=(0, 0, 0)
2025-08-24 16:34:55,192 - INFO - Program stopped by user
2025-08-24 16:38:17,507 - INFO - Sensor read successful: Indoor=(4, 6, 7), Outdoor=(3, 4, 5)
2025-08-24 16:38:27,508 - INFO - Sensor read successful: Indoor=(4, 6, 7), Outdoor=(3, 5, 5)
2025-08-24 16:38:37,508 - INFO - Sensor read successful: Indoor=(4, 6, 7), Outdoor=(3, 5, 5)
2025-08-24 16:38:47,509 - INFO - Sensor read successful: Indoor=(4, 6, 7), Outdoor=(3, 5, 5)
2025-08-24 16:38:57,509 - INFO - Sensor read successful: Indoor=(4, 6, 7), Outdoor=(3, 4, 5)
2025-08-24 16:39:07,510 - INFO - Sensor read successful: Indoor=(4, 6, 7), Outdoor=(3, 4, 5)
2025-08-24 16:39:17,510 - INFO - Sensor read successful: Indoor=(4, 6, 7), Outdoor=(3, 4, 5)
2025-08-24 16:39:27,511 - INFO - Sensor read successful: Indoor=(5, 7, 7), Outdoor=(3, 4, 4)
2025-08-24 16:39:37,511 - INFO - Sensor read successful: Indoor=(5, 7, 7), Outdoor=(3, 4, 4)
2025-08-24 16:39:47,512 - INFO - Sensor read successful: Indoor=(5, 7, 7), Outdoor=(3, 4, 4)
2025-08-24 16:39:57,512 - INFO - Sensor read successful: Indoor=(5, 7, 7), Outdoor=(2, 4, 4)
2025-08-24 16:40:07,513 - INFO - Sensor read successful: Indoor=(5, 7, 7), Outdoor=(2, 4, 4)
2025-08-24 16:40:17,514 - INFO - Sensor read successful: Indoor=(5, 7, 7), Outdoor=(2, 4, 4)
2025-08-24 16:40:27,514 - INFO - Sensor read successful: Indoor=(5, 7, 7), Outdoor=(3, 4, 5)
2025-08-24 16:40:37,519 - INFO - Sensor read successful: Indoor=(5, 7, 7), Outdoor=(3, 4, 5)
2025-08-24 16:40:47,519 - INFO - Sensor read successful: Indoor=(5, 7, 7), Outdoor=(3, 4, 5)
2025-08-24 16:40:57,521 - INFO - Sensor read successful: Indoor=(5, 7, 7), Outdoor=(3, 5, 5)
2025-08-24 16:41:07,521 - INFO - Sensor read successful: Indoor=(4, 6, 6), Outdoor=(3, 5, 5)
2025-08-24 16:41:17,522 - INFO - Sensor read successful: Indoor=(4, 6, 6), Outdoor=(3, 5, 5)
2025-08-24 16:41:27,523 - INFO - Sensor read successful: Indoor=(4, 6, 6), Outdoor=(3, 5, 5)
2025-08-24 16:41:37,523 - INFO - Sensor read successful: Indoor=(4, 6, 6), Outdoor=(3, 5, 5)
2025-08-24 16:41:47,524 - INFO - Sensor read successful: Indoor=(4, 6, 6), Outdoor=(3, 5, 5)
2025-08-24 16:41:57,524 - INFO - Sensor read successful: Indoor=(4, 6, 6), Outdoor=(3, 5, 5)
2025-08-24 16:42:07,525 - INFO - Sensor read successful: Indoor=(4, 6, 6), Outdoor=(3, 5, 5)
2025-08-24 16:42:17,526 - INFO - Sensor read successful: Indoor=(5, 7, 7), Outdoor=(3, 5, 5)
2025-08-24 16:42:27,526 - INFO - Sensor read successful: Indoor=(5, 8, 9), Outdoor=(2, 4, 5)
2025-08-24 16:42:37,526 - INFO - Sensor read successful: Indoor=(5, 8, 9), Outdoor=(2, 4, 5)
2025-08-24 16:42:47,527 - INFO - Sensor read successful: Indoor=(5, 8, 9), Outdoor=(2, 4, 5)
2025-08-24 16:42:57,527 - INFO - Sensor read successful: Indoor=(5, 7, 8), Outdoor=(3, 5, 5)
2025-08-24 16:43:07,528 - INFO - Sensor read successful: Indoor=(5, 7, 8), Outdoor=(3, 5, 5)
2025-08-24 16:43:17,528 - INFO - Sensor read successful: Indoor=(5, 7, 8), Outdoor=(3, 5, 5)
2025-08-24 16:43:27,529 - INFO - Sensor read successful: Indoor=(5, 7, 8), Outdoor=(3, 5, 5)
2025-08-24 16:43:37,529 - INFO - Sensor read successful: Indoor=(5, 7, 8), Outdoor=(3, 5, 5)
2025-08-24 16:43:47,530 - INFO - Sensor read successful: Indoor=(5, 7, 8), Outdoor=(3, 5, 5)
2025-08-24 16:43:57,530 - INFO - Sensor read successful: Indoor=(5, 7, 8), Outdoor=(3, 5, 5)
2025-08-24 16:44:07,531 - INFO - Sensor read successful: Indoor=(5, 7, 8), Outdoor=(3, 5, 5)
2025-08-24 16:44:17,531 - INFO - Sensor read successful: Indoor=(5, 7, 8), Outdoor=(3, 5, 5)
2025-08-24 16:44:27,532 - INFO - Sensor read successful: Indoor=(5, 8, 9), Outdoor=(3, 5, 5)
2025-08-24 16:44:37,532 - INFO - Sensor read successful: Indoor=(5, 8, 9), Outdoor=(3, 5, 5)
2025-08-24 16:44:47,533 - INFO - Sensor read successful: Indoor=(5, 8, 9), Outdoor=(3, 5, 5)
2025-08-24 16:44:57,533 - INFO - Sensor read successful: Indoor=(6, 9, 10), Outdoor=(3, 5, 5)
2025-08-24 16:45:07,534 - INFO - Sensor read successful: Indoor=(7, 10, 11), Outdoor=(3, 5, 5)
2025-08-24 16:45:17,535 - INFO - Sensor read successful: Indoor=(7, 10, 11), Outdoor=(3, 5, 5)
2025-08-24 16:45:27,535 - INFO - Sensor read successful: Indoor=(7, 10, 12), Outdoor=(3, 5, 6)
2025-08-24 16:45:37,541 - INFO - Sensor read successful: Indoor=(7, 10, 12), Outdoor=(2, 4, 5)
2025-08-24 16:45:47,541 - INFO - Sensor read successful: Indoor=(7, 10, 12), Outdoor=(2, 4, 5)
2025-08-24 16:45:57,542 - INFO - Sensor read successful: Indoor=(8, 12, 14), Outdoor=(2, 4, 5)
2025-08-24 16:46:07,542 - INFO - Sensor read successful: Indoor=(9, 13, 15), Outdoor=(3, 5, 6)
2025-08-24 16:46:17,543 - INFO - Sensor read successful: Indoor=(8, 13, 15), Outdoor=(3, 5, 6)
2025-08-24 16:46:27,543 - INFO - Sensor read successful: Indoor=(9, 13, 14), Outdoor=(3, 6, 6)
2025-08-24 16:46:32,442 - INFO - Program stopped by user
2025-08-24 16:54:18,727 - INFO - Sensor read successful: Indoor=(5, 8, 8), Outdoor=(4, 6, 6)
2025-08-24 16:54:28,728 - INFO - Sensor read successful: Indoor=(5, 8, 8), Outdoor=(4, 6, 6)
2025-08-24 16:54:38,729 - INFO - Sensor read successful: Indoor=(5, 8, 8), Outdoor=(3, 5, 6)
2025-08-24 16:54:48,729 - INFO - Sensor read successful: Indoor=(5, 8, 8), Outdoor=(3, 5, 6)
2025-08-24 16:54:58,730 - INFO - Sensor read successful: Indoor=(5, 8, 8), Outdoor=(3, 5, 6)
2025-08-24 16:55:08,730 - INFO - Sensor read successful: Indoor=(5, 8, 8), Outdoor=(4, 5, 6)
2025-08-24 16:55:18,731 - INFO - Sensor read successful: Indoor=(5, 8, 8), Outdoor=(4, 5, 6)
2025-08-24 16:55:28,731 - INFO - Sensor read successful: Indoor=(5, 7, 7), Outdoor=(4, 5, 6)
2025-08-24 16:55:38,732 - INFO - Sensor read successful: Indoor=(5, 7, 7), Outdoor=(3, 6, 6)
2025-08-24 16:55:48,732 - INFO - Sensor read successful: Indoor=(5, 7, 7), Outdoor=(3, 6, 6)
2025-08-24 16:55:58,733 - INFO - Sensor read successful: Indoor=(5, 7, 7), Outdoor=(3, 6, 6)
2025-08-24 16:56:08,733 - INFO - Sensor read successful: Indoor=(5, 7, 7), Outdoor=(3, 6, 6)
2025-08-24 16:56:18,733 - INFO - Sensor read successful: Indoor=(5, 7, 7), Outdoor=(3, 6, 6)
2025-08-24 16:56:28,734 - INFO - Sensor read successful: Indoor=(4, 6, 6), Outdoor=(3, 6, 6)
2025-08-24 16:56:38,734 - INFO - Sensor read successful: Indoor=(4, 6, 6), Outdoor=(3, 6, 6)
2025-08-24 16:56:48,735 - INFO - Sensor read successful: Indoor=(4, 6, 6), Outdoor=(3, 6, 6)
2025-08-24 16:56:58,735 - INFO - Sensor read successful: Indoor=(4, 6, 6), Outdoor=(3, 6, 6)
2025-08-24 16:57:08,735 - INFO - Sensor read successful: Indoor=(4, 6, 6), Outdoor=(3, 5, 5)
2025-08-24 16:57:18,736 - INFO - Sensor read successful: Indoor=(4, 6, 6), Outdoor=(3, 5, 5)
2025-08-24 16:57:28,736 - INFO - Sensor read successful: Indoor=(4, 6, 6), Outdoor=(3, 5, 5)
2025-08-24 16:57:38,737 - INFO - Sensor read successful: Indoor=(4, 6, 6), Outdoor=(3, 5, 5)
2025-08-24 16:57:48,738 - INFO - Sensor read successful: Indoor=(4, 6, 6), Outdoor=(3, 5, 5)
2025-08-24 16:57:58,738 - INFO - Sensor read successful: Indoor=(4, 7, 7), Outdoor=(3, 5, 5)
2025-08-24 16:58:08,739 - INFO - Sensor read successful: Indoor=(5, 8, 8), Outdoor=(3, 6, 6)
2025-08-24 16:58:18,739 - INFO - Sensor read successful: Indoor=(5, 8, 8), Outdoor=(3, 6, 6)
2025-08-24 16:58:28,740 - INFO - Sensor read successful: Indoor=(5, 8, 8), Outdoor=(3, 6, 6)
2025-08-24 16:58:38,740 - INFO - Sensor read successful: Indoor=(5, 8, 8), Outdoor=(4, 6, 6)
2025-08-24 16:58:48,741 - INFO - Sensor read successful: Indoor=(5, 8, 8), Outdoor=(4, 6, 6)
2025-08-24 16:58:58,741 - INFO - Sensor read successful: Indoor=(5, 8, 8), Outdoor=(4, 6, 6)
2025-08-24 16:59:08,742 - INFO - Sensor read successful: Indoor=(5, 8, 8), Outdoor=(3, 6, 6)
2025-08-24 16:59:18,742 - INFO - Sensor read successful: Indoor=(5, 8, 8), Outdoor=(3, 6, 6)
2025-08-24 16:59:28,743 - INFO - Sensor read successful: Indoor=(5, 8, 8), Outdoor=(3, 6, 6)
2025-08-24 16:59:38,743 - INFO - Sensor read successful: Indoor=(5, 8, 8), Outdoor=(3, 6, 6)
2025-08-24 16:59:48,744 - INFO - Sensor read successful: Indoor=(5, 8, 8), Outdoor=(3, 6, 6)
2025-08-24 16:59:58,744 - INFO - Sensor read successful: Indoor=(4, 7, 7), Outdoor=(3, 6, 6)
2025-08-24 17:00:08,745 - INFO - Sensor read successful: Indoor=(4, 7, 7), Outdoor=(3, 7, 7)
2025-08-24 17:00:18,745 - INFO - Sensor read successful: Indoor=(4, 7, 7), Outdoor=(3, 7, 7)
2025-08-24 17:00:28,746 - INFO - Sensor read successful: Indoor=(4, 8, 8), Outdoor=(3, 7, 7)
2025-08-24 17:00:38,746 - INFO - Sensor read successful: Indoor=(4, 8, 8), Outdoor=(3, 6, 6)
2025-08-24 17:00:48,747 - INFO - Sensor read successful: Indoor=(4, 8, 8), Outdoor=(3, 6, 6)
2025-08-24 17:00:58,747 - INFO - Sensor read successful: Indoor=(4, 8, 8), Outdoor=(3, 6, 6)
2025-08-24 17:01:08,748 - INFO - Sensor read successful: Indoor=(4, 8, 8), Outdoor=(4, 6, 6)
2025-08-24 17:01:18,748 - INFO - Sensor read successful: Indoor=(4, 8, 8), Outdoor=(4, 6, 6)
2025-08-24 17:01:28,749 - INFO - Sensor read successful: Indoor=(4, 8, 8), Outdoor=(4, 6, 6)
2025-08-24 17:01:38,749 - INFO - Sensor read successful: Indoor=(5, 9, 9), Outdoor=(3, 5, 5)
2025-08-24 17:01:48,750 - INFO - Sensor read successful: Indoor=(5, 9, 9), Outdoor=(3, 5, 5)
2025-08-24 17:01:58,750 - INFO - Sensor read successful: Indoor=(4, 9, 9), Outdoor=(3, 5, 5)
2025-08-24 17:02:08,750 - INFO - Sensor read successful: Indoor=(4, 9, 9), Outdoor=(4, 7, 7)
2025-08-24 17:02:18,751 - INFO - Sensor read successful: Indoor=(4, 9, 9), Outdoor=(4, 7, 7)
2025-08-24 17:02:28,751 - INFO - Sensor read successful: Indoor=(5, 8, 8), Outdoor=(4, 7, 7)
2025-08-24 17:02:38,752 - INFO - Sensor read successful: Indoor=(5, 8, 8), Outdoor=(4, 7, 7)
2025-08-24 17:02:48,752 - INFO - Sensor read successful: Indoor=(5, 8, 8), Outdoor=(4, 7, 7)
2025-08-24 17:02:58,753 - INFO - Sensor read successful: Indoor=(4, 7, 7), Outdoor=(4, 7, 7)
2025-08-24 17:03:08,754 - INFO - Sensor read successful: Indoor=(4, 7, 7), Outdoor=(4, 7, 7)
2025-08-24 17:03:18,754 - INFO - Sensor read successful: Indoor=(3, 6, 6), Outdoor=(3, 6, 6)
2025-08-24 17:03:28,755 - INFO - Sensor read successful: Indoor=(3, 6, 6), Outdoor=(3, 6, 6)
2025-08-24 17:03:38,755 - INFO - Sensor read successful: Indoor=(3, 6, 6), Outdoor=(3, 6, 6)
2025-08-24 17:03:48,756 - INFO - Sensor read successful: Indoor=(3, 6, 6), Outdoor=(4, 7, 7)
2025-08-24 17:03:58,756 - INFO - Sensor read successful: Indoor=(3, 6, 6), Outdoor=(4, 7, 7)
2025-08-24 17:04:08,757 - INFO - Sensor read successful: Indoor=(3, 6, 6), Outdoor=(3, 6, 7)
2025-08-24 17:04:18,757 - INFO - Sensor read successful: Indoor=(3, 6, 6), Outdoor=(3, 6, 7)
2025-08-24 17:04:28,757 - INFO - Sensor read successful: Indoor=(3, 5, 5), Outdoor=(3, 6, 7)
2025-08-24 17:04:38,758 - INFO - Sensor read successful: Indoor=(3, 5, 5), Outdoor=(4, 7, 7)
2025-08-24 17:04:48,758 - INFO - Sensor read successful: Indoor=(3, 5, 5), Outdoor=(4, 7, 7)
2025-08-24 17:04:58,759 - INFO - Sensor read successful: Indoor=(4, 6, 6), Outdoor=(3, 6, 6)
2025-08-24 17:05:08,759 - INFO - Sensor read successful: Indoor=(5, 7, 7), Outdoor=(3, 5, 6)
2025-08-24 17:05:18,760 - INFO - Sensor read successful: Indoor=(5, 7, 7), Outdoor=(3, 5, 6)
2025-08-24 17:05:28,760 - INFO - Sensor read successful: Indoor=(5, 7, 7), Outdoor=(4, 6, 7)
2025-08-24 17:05:38,760 - INFO - Sensor read successful: Indoor=(5, 7, 7), Outdoor=(4, 6, 7)
2025-08-24 17:05:48,761 - INFO - Sensor read successful: Indoor=(5, 7, 7), Outdoor=(4, 6, 7)
2025-08-24 17:05:58,761 - INFO - Sensor read successful: Indoor=(5, 7, 7), Outdoor=(4, 6, 7)
2025-08-24 17:06:08,761 - INFO - Sensor read successful: Indoor=(5, 7, 7), Outdoor=(4, 6, 7)
2025-08-24 17:06:18,762 - INFO - Sensor read successful: Indoor=(5, 7, 7), Outdoor=(4, 6, 7)
2025-08-24 17:06:28,762 - INFO - Sensor read successful: Indoor=(5, 6, 6), Outdoor=(4, 6, 7)
2025-08-24 17:06:38,763 - INFO - Sensor read successful: Indoor=(5, 6, 6), Outdoor=(4, 6, 6)
2025-08-24 17:06:48,763 - INFO - Sensor read successful: Indoor=(4, 5, 5), Outdoor=(4, 6, 6)
2025-08-24 17:06:58,767 - INFO - Sensor read successful: Indoor=(4, 6, 6), Outdoor=(4, 6, 6)
2025-08-24 17:07:08,768 - INFO - Sensor read successful: Indoor=(4, 6, 6), Outdoor=(3, 6, 6)
2025-08-24 17:07:18,768 - INFO - Sensor read successful: Indoor=(4, 6, 6), Outdoor=(3, 6, 6)
2025-08-24 17:07:28,768 - INFO - Sensor read successful: Indoor=(4, 6, 6), Outdoor=(3, 6, 6)
2025-08-24 17:07:38,769 - INFO - Sensor read successful: Indoor=(4, 6, 6), Outdoor=(3, 6, 6)
2025-08-24 17:07:48,769 - INFO - Sensor read successful: Indoor=(4, 6, 6), Outdoor=(3, 6, 6)
2025-08-24 17:07:58,770 - INFO - Sensor read successful: Indoor=(4, 6, 6), Outdoor=(3, 6, 6)
2025-08-24 17:08:08,775 - INFO - Sensor read successful: Indoor=(4, 6, 6), Outdoor=(3, 6, 6)
2025-08-24 17:08:18,775 - INFO - Sensor read successful: Indoor=(4, 6, 6), Outdoor=(3, 6, 6)
2025-08-24 17:08:28,776 - INFO - Sensor read successful: Indoor=(6, 7, 7), Outdoor=(3, 6, 6)
2025-08-24 17:08:38,776 - INFO - Sensor read successful: Indoor=(6, 7, 7), Outdoor=(3, 5, 5)
2025-08-24 17:08:48,777 - INFO - Sensor read successful: Indoor=(6, 7, 7), Outdoor=(3, 5, 5)
2025-08-24 17:08:58,777 - INFO - Sensor read successful: Indoor=(6, 7, 7), Outdoor=(3, 5, 5)
2025-08-24 17:09:08,778 - INFO - Sensor read successful: Indoor=(6, 7, 7), Outdoor=(4, 6, 6)
2025-08-24 17:09:18,778 - INFO - Sensor read successful: Indoor=(6, 7, 7), Outdoor=(4, 6, 6)
2025-08-24 17:09:28,779 - INFO - Sensor read successful: Indoor=(6, 8, 8), Outdoor=(4, 6, 6)
2025-08-24 17:09:38,780 - INFO - Sensor read successful: Indoor=(6, 8, 8), Outdoor=(3, 5, 6)
2025-08-24 17:09:48,780 - INFO - Sensor read successful: Indoor=(6, 8, 8), Outdoor=(3, 5, 6)
2025-08-24 17:09:58,781 - INFO - Sensor read successful: Indoor=(5, 7, 7), Outdoor=(3, 5, 6)
2025-08-24 17:10:08,781 - INFO - Sensor read successful: Indoor=(4, 6, 6), Outdoor=(3, 5, 6)
2025-08-24 17:10:18,782 - INFO - Sensor read successful: Indoor=(4, 6, 6), Outdoor=(3, 5, 6)
2025-08-24 17:10:28,782 - INFO - Sensor read successful: Indoor=(4, 7, 7), Outdoor=(3, 5, 6)
2025-08-24 17:10:38,783 - INFO - Sensor read successful: Indoor=(4, 7, 7), Outdoor=(3, 5, 6)
2025-08-24 17:10:48,783 - INFO - Sensor read successful: Indoor=(4, 7, 7), Outdoor=(3, 5, 6)
2025-08-24 17:10:58,783 - INFO - Sensor read successful: Indoor=(5, 7, 7), Outdoor=(3, 5, 6)
2025-08-24 17:11:08,784 - INFO - Sensor read successful: Indoor=(5, 7, 7), Outdoor=(2, 4, 5)
2025-08-24 17:11:18,785 - INFO - Sensor read successful: Indoor=(5, 7, 7), Outdoor=(2, 4, 5)
2025-08-24 17:11:28,786 - INFO - Sensor read successful: Indoor=(5, 8, 8), Outdoor=(2, 4, 5)
2025-08-24 17:11:38,786 - INFO - Sensor read successful: Indoor=(5, 8, 8), Outdoor=(2, 4, 6)
2025-08-24 17:11:48,787 - INFO - Sensor read successful: Indoor=(5, 8, 8), Outdoor=(3, 5, 7)
2025-08-24 17:11:58,787 - INFO - Sensor read successful: Indoor=(5, 8, 8), Outdoor=(3, 5, 7)
2025-08-24 17:12:08,788 - INFO - Sensor read successful: Indoor=(5, 8, 8), Outdoor=(3, 6, 7)
2025-08-24 17:12:18,788 - INFO - Sensor read successful: Indoor=(5, 8, 8), Outdoor=(3, 6, 7)
2025-08-24 17:12:28,789 - INFO - Sensor read successful: Indoor=(5, 8, 8), Outdoor=(3, 6, 7)
2025-08-24 17:12:38,790 - INFO - Sensor read successful: Indoor=(5, 8, 8), Outdoor=(3, 6, 7)
2025-08-24 17:12:48,790 - INFO - Sensor read successful: Indoor=(5, 8, 8), Outdoor=(3, 6, 7)
2025-08-24 17:12:58,791 - INFO - Sensor read successful: Indoor=(5, 8, 8), Outdoor=(2, 5, 6)
2025-08-24 19:58:43,843 - INFO - Sensor read successful: Indoor=(13, 24, 24), Outdoor=(11, 16, 18)
2025-08-24 19:58:53,844 - INFO - Sensor read successful: Indoor=(12, 24, 24), Outdoor=(11, 16, 18)
2025-08-24 19:59:03,844 - INFO - Sensor read successful: Indoor=(12, 24, 24), Outdoor=(11, 17, 18)
2025-08-24 19:59:13,845 - INFO - Sensor read successful: Indoor=(12, 24, 24), Outdoor=(11, 17, 18)
2025-08-24 19:59:23,846 - INFO - Sensor read successful: Indoor=(12, 24, 26), Outdoor=(11, 17, 18)
2025-08-24 19:59:33,846 - INFO - Sensor read successful: Indoor=(12, 24, 26), Outdoor=(11, 17, 18)
2025-08-24 19:59:43,846 - INFO - Sensor read successful: Indoor=(12, 24, 26), Outdoor=(11, 17, 18)
2025-08-24 19:59:53,847 - INFO - Sensor read successful: Indoor=(12, 22, 25), Outdoor=(11, 17, 18)
2025-08-24 20:00:03,847 - INFO - Sensor read successful: Indoor=(12, 22, 25), Outdoor=(11, 17, 18)
2025-08-24 20:00:13,848 - INFO - Sensor read successful: Indoor=(12, 22, 25), Outdoor=(11, 17, 18)
2025-08-24 20:00:23,848 - INFO - Sensor read successful: Indoor=(12, 22, 24), Outdoor=(11, 17, 18)
2025-08-24 20:00:33,849 - INFO - Sensor read successful: Indoor=(12, 22, 24), Outdoor=(11, 17, 18)
2025-08-24 20:00:43,849 - INFO - Sensor read successful: Indoor=(12, 22, 24), Outdoor=(11, 17, 18)
2025-08-24 20:00:53,850 - INFO - Sensor read successful: Indoor=(12, 21, 23), Outdoor=(11, 17, 18)
2025-08-24 20:01:03,851 - INFO - Sensor read successful: Indoor=(12, 21, 23), Outdoor=(11, 17, 18)
2025-08-24 20:01:13,851 - INFO - Sensor read successful: Indoor=(12, 21, 23), Outdoor=(11, 17, 18)
2025-08-24 20:01:23,852 - INFO - Sensor read successful: Indoor=(12, 21, 24), Outdoor=(11, 17, 18)
2025-08-24 20:01:33,852 - INFO - Sensor read successful: Indoor=(12, 21, 24), Outdoor=(11, 16, 18)
2025-08-24 20:01:43,852 - INFO - Sensor read successful: Indoor=(12, 21, 24), Outdoor=(12, 17, 19)
2025-08-24 20:01:53,853 - INFO - Sensor read successful: Indoor=(13, 23, 25), Outdoor=(12, 17, 19)
2025-08-24 20:02:03,853 - INFO - Sensor read successful: Indoor=(13, 23, 25), Outdoor=(12, 18, 19)
2025-08-24 20:02:13,859 - INFO - Sensor read successful: Indoor=(13, 23, 25), Outdoor=(12, 18, 19)
2025-08-24 20:02:23,859 - INFO - Sensor read successful: Indoor=(13, 23, 25), Outdoor=(12, 18, 19)
2025-08-24 20:02:33,860 - INFO - Sensor read successful: Indoor=(13, 23, 26), Outdoor=(12, 18, 19)
2025-08-24 20:02:43,860 - INFO - Sensor read successful: Indoor=(14, 23, 26), Outdoor=(12, 18, 19)
2025-08-24 20:02:53,861 - INFO - Sensor read successful: Indoor=(13, 23, 25), Outdoor=(11, 17, 18)
2025-08-24 20:03:03,862 - INFO - Sensor read successful: Indoor=(14, 24, 24), Outdoor=(11, 17, 18)
2025-08-24 20:03:13,862 - INFO - Sensor read successful: Indoor=(14, 24, 24), Outdoor=(11, 17, 18)
2025-08-24 20:03:23,863 - INFO - Sensor read successful: Indoor=(14, 24, 24), Outdoor=(11, 17, 18)
2025-08-24 20:03:33,863 - INFO - Sensor read successful: Indoor=(13, 26, 26), Outdoor=(12, 18, 19)
2025-08-24 20:03:43,864 - INFO - Sensor read successful: Indoor=(13, 25, 26), Outdoor=(12, 18, 19)
2025-08-24 20:03:53,864 - INFO - Sensor read successful: Indoor=(13, 23, 24), Outdoor=(12, 18, 20)
2025-08-24 20:04:03,865 - INFO - Sensor read successful: Indoor=(12, 23, 24), Outdoor=(12, 18, 20)
2025-08-24 20:04:13,865 - INFO - Sensor read successful: Indoor=(13, 25, 25), Outdoor=(11, 17, 19)
2025-08-24 20:04:23,866 - INFO - Sensor read successful: Indoor=(13, 24, 25), Outdoor=(11, 17, 19)
2025-08-24 20:04:33,867 - INFO - Sensor read successful: Indoor=(13, 23, 24), Outdoor=(12, 18, 20)
2025-08-24 20:04:43,867 - INFO - Sensor read successful: Indoor=(12, 22, 23), Outdoor=(11, 17, 19)
2025-08-24 20:04:53,868 - INFO - Sensor read successful: Indoor=(12, 21, 24), Outdoor=(11, 18, 20)
2025-08-24 20:05:03,868 - INFO - Sensor read successful: Indoor=(12, 21, 24), Outdoor=(12, 20, 22)
2025-08-24 20:05:13,869 - INFO - Sensor read successful: Indoor=(12, 21, 24), Outdoor=(11, 18, 19)
2025-08-24 20:05:23,869 - INFO - Sensor read successful: Indoor=(12, 20, 24), Outdoor=(10, 18, 20)
2025-08-24 20:05:33,870 - INFO - Sensor read successful: Indoor=(12, 20, 24), Outdoor=(9, 17, 18)
2025-08-24 20:05:43,871 - INFO - Sensor read successful: Indoor=(12, 20, 24), Outdoor=(9, 17, 18)
2025-08-24 20:05:53,871 - INFO - Sensor read successful: Indoor=(12, 20, 24), Outdoor=(9, 17, 18)
2025-08-24 20:06:03,872 - INFO - Sensor read successful: Indoor=(12, 20, 24), Outdoor=(9, 17, 18)
2025-08-24 20:06:13,872 - INFO - Sensor read successful: Indoor=(12, 20, 24), Outdoor=(9, 17, 18)
2025-08-24 20:06:23,873 - INFO - Sensor read successful: Indoor=(12, 19, 22), Outdoor=(9, 17, 18)
2025-08-24 20:06:33,874 - INFO - Sensor read successful: Indoor=(12, 19, 22), Outdoor=(10, 17, 18)
2025-08-24 20:06:43,874 - INFO - Sensor read successful: Indoor=(12, 19, 22), Outdoor=(10, 17, 18)
2025-08-24 20:06:53,875 - INFO - Sensor read successful: Indoor=(13, 19, 22), Outdoor=(10, 17, 18)
2025-08-24 20:07:03,875 - INFO - Sensor read successful: Indoor=(13, 19, 22), Outdoor=(9, 16, 17)
2025-08-24 20:07:13,876 - INFO - Sensor read successful: Indoor=(13, 19, 22), Outdoor=(9, 16, 17)
2025-08-24 20:07:23,876 - INFO - Sensor read successful: Indoor=(13, 21, 24), Outdoor=(9, 16, 17)
2025-08-24 20:07:33,877 - INFO - Sensor read successful: Indoor=(13, 21, 24), Outdoor=(9, 15, 16)
2025-08-24 20:07:43,877 - INFO - Sensor read successful: Indoor=(14, 20, 23), Outdoor=(9, 15, 16)
2025-08-24 20:07:53,878 - INFO - Sensor read successful: Indoor=(13, 21, 24), Outdoor=(9, 15, 16)
2025-08-24 20:08:04,618 - INFO - Sensor read successful: Indoor=(15, 20, 22), Outdoor=(11, 17, 24)
2025-08-24 20:08:14,619 - INFO - Sensor read successful: Indoor=(14, 20, 22), Outdoor=(11, 18, 23)
2025-08-24 20:08:24,626 - INFO - Sensor read successful: Indoor=(14, 21, 22), Outdoor=(11, 18, 24)
2025-08-24 20:08:34,626 - INFO - Sensor read successful: Indoor=(14, 21, 22), Outdoor=(12, 19, 25)
2025-08-24 20:08:44,627 - INFO - Sensor read successful: Indoor=(15, 22, 23), Outdoor=(12, 18, 25)
2025-08-24 20:08:54,627 - INFO - Sensor read successful: Indoor=(16, 22, 25), Outdoor=(11, 17, 21)
2025-08-24 20:09:04,628 - INFO - Sensor read successful: Indoor=(15, 22, 25), Outdoor=(11, 17, 21)
2025-08-24 20:09:14,628 - INFO - Sensor read successful: Indoor=(16, 22, 25), Outdoor=(11, 16, 20)
2025-08-24 20:09:24,628 - INFO - Sensor read successful: Indoor=(16, 23, 26), Outdoor=(11, 16, 20)
2025-08-24 20:09:34,629 - INFO - Sensor read successful: Indoor=(15, 22, 23), Outdoor=(11, 16, 19)
2025-08-24 20:09:44,629 - INFO - Sensor read successful: Indoor=(15, 23, 24), Outdoor=(11, 15, 17)
2025-08-24 20:09:54,630 - INFO - Sensor read successful: Indoor=(15, 22, 24), Outdoor=(11, 15, 17)
2025-08-24 20:10:04,630 - INFO - Sensor read successful: Indoor=(16, 22, 23), Outdoor=(11, 16, 16)
2025-08-24 20:10:14,630 - INFO - Sensor read successful: Indoor=(16, 22, 24), Outdoor=(11, 15, 15)
2025-08-24 20:10:24,631 - INFO - Sensor read successful: Indoor=(16, 22, 24), Outdoor=(10, 14, 14)
2025-08-24 20:10:34,631 - INFO - Sensor read successful: Indoor=(16, 23, 23), Outdoor=(10, 14, 14)
2025-08-24 20:10:44,632 - INFO - Sensor read successful: Indoor=(16, 23, 23), Outdoor=(9, 13, 13)
2025-08-24 20:10:54,632 - INFO - Sensor read successful: Indoor=(15, 21, 21), Outdoor=(11, 15, 15)
2025-08-24 20:11:04,632 - INFO - Sensor read successful: Indoor=(15, 21, 21), Outdoor=(11, 17, 17)
2025-08-24 20:11:14,633 - INFO - Sensor read successful: Indoor=(14, 20, 20), Outdoor=(11, 17, 17)
2025-08-24 20:11:24,633 - INFO - Sensor read successful: Indoor=(13, 20, 21), Outdoor=(11, 17, 18)
2025-08-24 20:11:34,634 - INFO - Sensor read successful: Indoor=(14, 20, 23), Outdoor=(12, 19, 20)
2025-08-24 20:11:44,634 - INFO - Sensor read successful: Indoor=(14, 21, 24), Outdoor=(11, 18, 19)
2025-08-24 20:11:54,635 - INFO - Sensor read successful: Indoor=(14, 21, 24), Outdoor=(10, 18, 19)
2025-08-24 20:12:04,635 - INFO - Sensor read successful: Indoor=(13, 20, 23), Outdoor=(11, 18, 19)
2025-08-24 20:12:14,635 - INFO - Sensor read successful: Indoor=(12, 20, 23), Outdoor=(11, 18, 18)
2025-08-24 20:12:24,636 - INFO - Sensor read successful: Indoor=(12, 20, 23), Outdoor=(11, 17, 18)
2025-08-24 20:12:34,636 - INFO - Sensor read successful: Indoor=(12, 21, 26), Outdoor=(11, 17, 18)
2025-08-24 20:12:44,637 - INFO - Sensor read successful: Indoor=(12, 22, 26), Outdoor=(11, 17, 17)
2025-08-24 20:12:45,067 - INFO - Program stopped by user
2025-08-24 20:31:21,823 - INFO - Sensor read successful: Indoor=(17, 26, 27), Outdoor=(12, 18, 19)
2025-08-24 20:31:31,823 - INFO - Sensor read successful: Indoor=(17, 25, 27), Outdoor=(12, 18, 19)
2025-08-24 20:31:41,824 - INFO - Sensor read successful: Indoor=(18, 27, 30), Outdoor=(11, 18, 19)
2025-08-24 20:31:51,825 - INFO - Sensor read successful: Indoor=(19, 27, 30), Outdoor=(11, 19, 20)
2025-08-24 20:32:01,826 - INFO - Sensor read successful: Indoor=(19, 30, 32), Outdoor=(10, 18, 19)
2025-08-24 20:32:11,827 - INFO - Sensor read successful: Indoor=(19, 31, 35), Outdoor=(11, 19, 20)
2025-08-24 20:32:21,827 - INFO - Sensor read successful: Indoor=(18, 29, 32), Outdoor=(12, 20, 21)
2025-08-24 20:32:31,828 - INFO - Sensor read successful: Indoor=(18, 31, 37), Outdoor=(12, 21, 21)
2025-08-24 20:32:41,828 - INFO - Sensor read successful: Indoor=(17, 31, 41), Outdoor=(12, 21, 22)
2025-08-24 20:32:51,829 - INFO - Sensor read successful: Indoor=(17, 29, 37), Outdoor=(13, 23, 24)
2025-08-24 20:33:01,829 - INFO - Sensor read successful: Indoor=(19, 31, 38), Outdoor=(13, 25, 27)
2025-08-24 20:33:11,830 - INFO - Sensor read successful: Indoor=(20, 31, 38), Outdoor=(14, 24, 26)
2025-08-24 20:33:21,830 - INFO - Sensor read successful: Indoor=(20, 31, 37), Outdoor=(14, 24, 26)
2025-08-24 20:33:31,831 - INFO - Sensor read successful: Indoor=(19, 30, 36), Outdoor=(14, 25, 26)
2025-08-24 20:33:41,831 - INFO - Sensor read successful: Indoor=(18, 28, 32), Outdoor=(14, 25, 26)
2025-08-24 20:33:51,831 - INFO - Sensor read successful: Indoor=(17, 27, 32), Outdoor=(15, 25, 27)
2025-08-24 20:34:01,832 - INFO - Sensor read successful: Indoor=(17, 27, 32), Outdoor=(15, 24, 26)
2025-08-24 20:34:11,832 - INFO - Sensor read successful: Indoor=(17, 28, 32), Outdoor=(16, 24, 26)
2025-08-24 20:34:21,833 - INFO - Sensor read successful: Indoor=(19, 30, 33), Outdoor=(15, 23, 24)
2025-08-24 20:34:22,840 - INFO - Program stopped by user
2025-08-24 23:20:17,304 - INFO - Sensor read successful: Indoor=(7, 10, 10), Outdoor=(5, 8, 8)
2025-08-24 23:20:27,306 - INFO - Sensor read successful: Indoor=(7, 9, 9), Outdoor=(4, 6, 6)
2025-08-24 23:20:37,307 - INFO - Sensor read successful: Indoor=(6, 9, 9), Outdoor=(3, 6, 7)
2025-08-24 23:20:47,308 - INFO - Sensor read successful: Indoor=(7, 9, 11), Outdoor=(3, 6, 7)
2025-08-24 23:20:57,308 - INFO - Sensor read successful: Indoor=(8, 11, 12), Outdoor=(3, 6, 7)
2025-08-24 23:21:07,309 - INFO - Sensor read successful: Indoor=(8, 10, 12), Outdoor=(4, 7, 8)
2025-08-24 23:21:17,309 - INFO - Sensor read successful: Indoor=(7, 11, 12), Outdoor=(4, 6, 8)
2025-08-24 23:21:27,309 - INFO - Sensor read successful: Indoor=(7, 10, 11), Outdoor=(4, 6, 8)
2025-08-24 23:21:37,310 - INFO - Sensor read successful: Indoor=(8, 10, 12), Outdoor=(5, 6, 8)
2025-08-24 23:21:47,311 - INFO - Sensor read successful: Indoor=(6, 9, 11), Outdoor=(5, 7, 8)
2025-08-24 23:21:57,312 - INFO - Sensor read successful: Indoor=(7, 10, 11), Outdoor=(5, 6, 8)
2025-08-24 23:22:07,312 - INFO - Sensor read successful: Indoor=(6, 9, 10), Outdoor=(5, 7, 8)
2025-08-24 23:22:17,313 - INFO - Sensor read successful: Indoor=(6, 9, 11), Outdoor=(4, 7, 7)
2025-08-24 23:22:27,804 - INFO - Sensor read successful: Indoor=(6, 10, 10), Outdoor=(4, 6, 6)
2025-08-24 23:22:38,191 - INFO - Sensor read successful: Indoor=(5, 8, 10), Outdoor=(4, 7, 7)
2025-08-24 23:22:48,192 - INFO - Sensor read successful: Indoor=(5, 8, 10), Outdoor=(5, 7, 7)
2025-08-24 23:22:58,192 - INFO - Sensor read successful: Indoor=(6, 8, 12), Outdoor=(5, 8, 8)
2025-08-24 23:23:08,193 - INFO - Sensor read successful: Indoor=(6, 8, 12), Outdoor=(5, 8, 8)
2025-08-24 23:37:05,865 - INFO - Firestore sink enabled (collection='pm_readings', batch=50, flush=30s)
2025-08-24 23:37:05,866 - INFO - Program started.
2025-08-24 23:37:06,044 - INFO - Sensor OK: Indoor=(7.0, 9.0, 11.0), Outdoor=(5.0, 7.0, 7.0)
2025-08-24 23:37:16,045 - INFO - Sensor OK: Indoor=(7.0, 10.0, 12.0), Outdoor=(5.0, 7.0, 7.0)
2025-08-24 23:37:26,046 - INFO - Sensor OK: Indoor=(7.0, 10.0, 12.0), Outdoor=(5.0, 7.0, 7.0)
2025-08-24 23:37:36,047 - INFO - Sensor OK: Indoor=(7.0, 10.0, 12.0), Outdoor=(5.0, 7.0, 8.0)
2025-08-24 23:37:36,467 - ERROR - AuthMetadataPluginCallback "<google.auth.transport.grpc.AuthMetadataPlugin object at 0x7fff2e3e4910>" raised exception!
Traceback (most recent call last):
  File "/home/chon/project/env/lib/python3.11/site-packages/grpc/_plugin_wrapping.py", line 105, in __call__
    self._metadata_plugin(
  File "/home/chon/project/env/lib/python3.11/site-packages/google/auth/transport/grpc.py", line 95, in __call__
    callback(self._get_authorization_headers(context), None)
             ^^^^^^^^^^^^^^^^^^^^^^^^^^^^^^^^^^^^^^^^
  File "/home/chon/project/env/lib/python3.11/site-packages/google/auth/transport/grpc.py", line 81, in _get_authorization_headers
    self._credentials.before_request(
  File "/home/chon/project/env/lib/python3.11/site-packages/google/auth/credentials.py", line 239, in before_request
    self._blocking_refresh(request)
  File "/home/chon/project/env/lib/python3.11/site-packages/google/auth/credentials.py", line 202, in _blocking_refresh
    self.refresh(request)
  File "/home/chon/project/env/lib/python3.11/site-packages/google/oauth2/service_account.py", line 448, in refresh
    access_token, expiry, _ = _client.jwt_grant(
                              ^^^^^^^^^^^^^^^^^^
  File "/home/chon/project/env/lib/python3.11/site-packages/google/oauth2/_client.py", line 299, in jwt_grant
    response_data = _token_endpoint_request(
                    ^^^^^^^^^^^^^^^^^^^^^^^^
  File "/home/chon/project/env/lib/python3.11/site-packages/google/oauth2/_client.py", line 270, in _token_endpoint_request
    _handle_error_response(response_data, retryable_error)
  File "/home/chon/project/env/lib/python3.11/site-packages/google/oauth2/_client.py", line 69, in _handle_error_response
    raise exceptions.RefreshError(
google.auth.exceptions.RefreshError: ('invalid_grant: Invalid JWT Signature.', {'error': 'invalid_grant', 'error_description': 'Invalid JWT Signature.'})
2025-08-24 23:37:36,579 - ERROR - AuthMetadataPluginCallback "<google.auth.transport.grpc.AuthMetadataPlugin object at 0x7fff2e3e4910>" raised exception!
Traceback (most recent call last):
  File "/home/chon/project/env/lib/python3.11/site-packages/grpc/_plugin_wrapping.py", line 105, in __call__
    self._metadata_plugin(
  File "/home/chon/project/env/lib/python3.11/site-packages/google/auth/transport/grpc.py", line 95, in __call__
    callback(self._get_authorization_headers(context), None)
             ^^^^^^^^^^^^^^^^^^^^^^^^^^^^^^^^^^^^^^^^
  File "/home/chon/project/env/lib/python3.11/site-packages/google/auth/transport/grpc.py", line 81, in _get_authorization_headers
    self._credentials.before_request(
  File "/home/chon/project/env/lib/python3.11/site-packages/google/auth/credentials.py", line 239, in before_request
    self._blocking_refresh(request)
  File "/home/chon/project/env/lib/python3.11/site-packages/google/auth/credentials.py", line 202, in _blocking_refresh
    self.refresh(request)
  File "/home/chon/project/env/lib/python3.11/site-packages/google/oauth2/service_account.py", line 448, in refresh
    access_token, expiry, _ = _client.jwt_grant(
                              ^^^^^^^^^^^^^^^^^^
  File "/home/chon/project/env/lib/python3.11/site-packages/google/oauth2/_client.py", line 299, in jwt_grant
    response_data = _token_endpoint_request(
                    ^^^^^^^^^^^^^^^^^^^^^^^^
  File "/home/chon/project/env/lib/python3.11/site-packages/google/oauth2/_client.py", line 270, in _token_endpoint_request
    _handle_error_response(response_data, retryable_error)
  File "/home/chon/project/env/lib/python3.11/site-packages/google/oauth2/_client.py", line 69, in _handle_error_response
    raise exceptions.RefreshError(
google.auth.exceptions.RefreshError: ('invalid_grant: Invalid JWT Signature.', {'error': 'invalid_grant', 'error_description': 'Invalid JWT Signature.'})
2025-08-24 23:37:36,698 - ERROR - AuthMetadataPluginCallback "<google.auth.transport.grpc.AuthMetadataPlugin object at 0x7fff2e3e4910>" raised exception!
Traceback (most recent call last):
  File "/home/chon/project/env/lib/python3.11/site-packages/grpc/_plugin_wrapping.py", line 105, in __call__
    self._metadata_plugin(
  File "/home/chon/project/env/lib/python3.11/site-packages/google/auth/transport/grpc.py", line 95, in __call__
    callback(self._get_authorization_headers(context), None)
             ^^^^^^^^^^^^^^^^^^^^^^^^^^^^^^^^^^^^^^^^
  File "/home/chon/project/env/lib/python3.11/site-packages/google/auth/transport/grpc.py", line 81, in _get_authorization_headers
    self._credentials.before_request(
  File "/home/chon/project/env/lib/python3.11/site-packages/google/auth/credentials.py", line 239, in before_request
    self._blocking_refresh(request)
  File "/home/chon/project/env/lib/python3.11/site-packages/google/auth/credentials.py", line 202, in _blocking_refresh
    self.refresh(request)
  File "/home/chon/project/env/lib/python3.11/site-packages/google/oauth2/service_account.py", line 448, in refresh
    access_token, expiry, _ = _client.jwt_grant(
                              ^^^^^^^^^^^^^^^^^^
  File "/home/chon/project/env/lib/python3.11/site-packages/google/oauth2/_client.py", line 299, in jwt_grant
    response_data = _token_endpoint_request(
                    ^^^^^^^^^^^^^^^^^^^^^^^^
  File "/home/chon/project/env/lib/python3.11/site-packages/google/oauth2/_client.py", line 270, in _token_endpoint_request
    _handle_error_response(response_data, retryable_error)
  File "/home/chon/project/env/lib/python3.11/site-packages/google/oauth2/_client.py", line 69, in _handle_error_response
    raise exceptions.RefreshError(
google.auth.exceptions.RefreshError: ('invalid_grant: Invalid JWT Signature.', {'error': 'invalid_grant', 'error_description': 'Invalid JWT Signature.'})
2025-08-24 23:37:36,867 - ERROR - AuthMetadataPluginCallback "<google.auth.transport.grpc.AuthMetadataPlugin object at 0x7fff2e3e4910>" raised exception!
Traceback (most recent call last):
  File "/home/chon/project/env/lib/python3.11/site-packages/grpc/_plugin_wrapping.py", line 105, in __call__
    self._metadata_plugin(
  File "/home/chon/project/env/lib/python3.11/site-packages/google/auth/transport/grpc.py", line 95, in __call__
    callback(self._get_authorization_headers(context), None)
             ^^^^^^^^^^^^^^^^^^^^^^^^^^^^^^^^^^^^^^^^
  File "/home/chon/project/env/lib/python3.11/site-packages/google/auth/transport/grpc.py", line 81, in _get_authorization_headers
    self._credentials.before_request(
  File "/home/chon/project/env/lib/python3.11/site-packages/google/auth/credentials.py", line 239, in before_request
    self._blocking_refresh(request)
  File "/home/chon/project/env/lib/python3.11/site-packages/google/auth/credentials.py", line 202, in _blocking_refresh
    self.refresh(request)
  File "/home/chon/project/env/lib/python3.11/site-packages/google/oauth2/service_account.py", line 448, in refresh
    access_token, expiry, _ = _client.jwt_grant(
                              ^^^^^^^^^^^^^^^^^^
  File "/home/chon/project/env/lib/python3.11/site-packages/google/oauth2/_client.py", line 299, in jwt_grant
    response_data = _token_endpoint_request(
                    ^^^^^^^^^^^^^^^^^^^^^^^^
  File "/home/chon/project/env/lib/python3.11/site-packages/google/oauth2/_client.py", line 270, in _token_endpoint_request
    _handle_error_response(response_data, retryable_error)
  File "/home/chon/project/env/lib/python3.11/site-packages/google/oauth2/_client.py", line 69, in _handle_error_response
    raise exceptions.RefreshError(
google.auth.exceptions.RefreshError: ('invalid_grant: Invalid JWT Signature.', {'error': 'invalid_grant', 'error_description': 'Invalid JWT Signature.'})
2025-08-24 23:37:37,000 - ERROR - AuthMetadataPluginCallback "<google.auth.transport.grpc.AuthMetadataPlugin object at 0x7fff2e3e4910>" raised exception!
Traceback (most recent call last):
  File "/home/chon/project/env/lib/python3.11/site-packages/grpc/_plugin_wrapping.py", line 105, in __call__
    self._metadata_plugin(
  File "/home/chon/project/env/lib/python3.11/site-packages/google/auth/transport/grpc.py", line 95, in __call__
    callback(self._get_authorization_headers(context), None)
             ^^^^^^^^^^^^^^^^^^^^^^^^^^^^^^^^^^^^^^^^
  File "/home/chon/project/env/lib/python3.11/site-packages/google/auth/transport/grpc.py", line 81, in _get_authorization_headers
    self._credentials.before_request(
  File "/home/chon/project/env/lib/python3.11/site-packages/google/auth/credentials.py", line 239, in before_request
    self._blocking_refresh(request)
  File "/home/chon/project/env/lib/python3.11/site-packages/google/auth/credentials.py", line 202, in _blocking_refresh
    self.refresh(request)
  File "/home/chon/project/env/lib/python3.11/site-packages/google/oauth2/service_account.py", line 448, in refresh
    access_token, expiry, _ = _client.jwt_grant(
                              ^^^^^^^^^^^^^^^^^^
  File "/home/chon/project/env/lib/python3.11/site-packages/google/oauth2/_client.py", line 299, in jwt_grant
    response_data = _token_endpoint_request(
                    ^^^^^^^^^^^^^^^^^^^^^^^^
  File "/home/chon/project/env/lib/python3.11/site-packages/google/oauth2/_client.py", line 270, in _token_endpoint_request
    _handle_error_response(response_data, retryable_error)
  File "/home/chon/project/env/lib/python3.11/site-packages/google/oauth2/_client.py", line 69, in _handle_error_response
    raise exceptions.RefreshError(
google.auth.exceptions.RefreshError: ('invalid_grant: Invalid JWT Signature.', {'error': 'invalid_grant', 'error_description': 'Invalid JWT Signature.'})
2025-08-24 23:37:37,214 - ERROR - AuthMetadataPluginCallback "<google.auth.transport.grpc.AuthMetadataPlugin object at 0x7fff2e3e4910>" raised exception!
Traceback (most recent call last):
  File "/home/chon/project/env/lib/python3.11/site-packages/grpc/_plugin_wrapping.py", line 105, in __call__
    self._metadata_plugin(
  File "/home/chon/project/env/lib/python3.11/site-packages/google/auth/transport/grpc.py", line 95, in __call__
    callback(self._get_authorization_headers(context), None)
             ^^^^^^^^^^^^^^^^^^^^^^^^^^^^^^^^^^^^^^^^
  File "/home/chon/project/env/lib/python3.11/site-packages/google/auth/transport/grpc.py", line 81, in _get_authorization_headers
    self._credentials.before_request(
  File "/home/chon/project/env/lib/python3.11/site-packages/google/auth/credentials.py", line 239, in before_request
    self._blocking_refresh(request)
  File "/home/chon/project/env/lib/python3.11/site-packages/google/auth/credentials.py", line 202, in _blocking_refresh
    self.refresh(request)
  File "/home/chon/project/env/lib/python3.11/site-packages/google/oauth2/service_account.py", line 448, in refresh
    access_token, expiry, _ = _client.jwt_grant(
                              ^^^^^^^^^^^^^^^^^^
  File "/home/chon/project/env/lib/python3.11/site-packages/google/oauth2/_client.py", line 299, in jwt_grant
    response_data = _token_endpoint_request(
                    ^^^^^^^^^^^^^^^^^^^^^^^^
  File "/home/chon/project/env/lib/python3.11/site-packages/google/oauth2/_client.py", line 270, in _token_endpoint_request
    _handle_error_response(response_data, retryable_error)
  File "/home/chon/project/env/lib/python3.11/site-packages/google/oauth2/_client.py", line 69, in _handle_error_response
    raise exceptions.RefreshError(
google.auth.exceptions.RefreshError: ('invalid_grant: Invalid JWT Signature.', {'error': 'invalid_grant', 'error_description': 'Invalid JWT Signature.'})
2025-08-24 23:37:37,481 - ERROR - AuthMetadataPluginCallback "<google.auth.transport.grpc.AuthMetadataPlugin object at 0x7fff2e3e4910>" raised exception!
Traceback (most recent call last):
  File "/home/chon/project/env/lib/python3.11/site-packages/grpc/_plugin_wrapping.py", line 105, in __call__
    self._metadata_plugin(
  File "/home/chon/project/env/lib/python3.11/site-packages/google/auth/transport/grpc.py", line 95, in __call__
    callback(self._get_authorization_headers(context), None)
             ^^^^^^^^^^^^^^^^^^^^^^^^^^^^^^^^^^^^^^^^
  File "/home/chon/project/env/lib/python3.11/site-packages/google/auth/transport/grpc.py", line 81, in _get_authorization_headers
    self._credentials.before_request(
  File "/home/chon/project/env/lib/python3.11/site-packages/google/auth/credentials.py", line 239, in before_request
    self._blocking_refresh(request)
  File "/home/chon/project/env/lib/python3.11/site-packages/google/auth/credentials.py", line 202, in _blocking_refresh
    self.refresh(request)
  File "/home/chon/project/env/lib/python3.11/site-packages/google/oauth2/service_account.py", line 448, in refresh
    access_token, expiry, _ = _client.jwt_grant(
                              ^^^^^^^^^^^^^^^^^^
  File "/home/chon/project/env/lib/python3.11/site-packages/google/oauth2/_client.py", line 299, in jwt_grant
    response_data = _token_endpoint_request(
                    ^^^^^^^^^^^^^^^^^^^^^^^^
  File "/home/chon/project/env/lib/python3.11/site-packages/google/oauth2/_client.py", line 270, in _token_endpoint_request
    _handle_error_response(response_data, retryable_error)
  File "/home/chon/project/env/lib/python3.11/site-packages/google/oauth2/_client.py", line 69, in _handle_error_response
    raise exceptions.RefreshError(
google.auth.exceptions.RefreshError: ('invalid_grant: Invalid JWT Signature.', {'error': 'invalid_grant', 'error_description': 'Invalid JWT Signature.'})
2025-08-24 23:37:37,602 - ERROR - AuthMetadataPluginCallback "<google.auth.transport.grpc.AuthMetadataPlugin object at 0x7fff2e3e4910>" raised exception!
Traceback (most recent call last):
  File "/home/chon/project/env/lib/python3.11/site-packages/grpc/_plugin_wrapping.py", line 105, in __call__
    self._metadata_plugin(
  File "/home/chon/project/env/lib/python3.11/site-packages/google/auth/transport/grpc.py", line 95, in __call__
    callback(self._get_authorization_headers(context), None)
             ^^^^^^^^^^^^^^^^^^^^^^^^^^^^^^^^^^^^^^^^
  File "/home/chon/project/env/lib/python3.11/site-packages/google/auth/transport/grpc.py", line 81, in _get_authorization_headers
    self._credentials.before_request(
  File "/home/chon/project/env/lib/python3.11/site-packages/google/auth/credentials.py", line 239, in before_request
    self._blocking_refresh(request)
  File "/home/chon/project/env/lib/python3.11/site-packages/google/auth/credentials.py", line 202, in _blocking_refresh
    self.refresh(request)
  File "/home/chon/project/env/lib/python3.11/site-packages/google/oauth2/service_account.py", line 448, in refresh
    access_token, expiry, _ = _client.jwt_grant(
                              ^^^^^^^^^^^^^^^^^^
  File "/home/chon/project/env/lib/python3.11/site-packages/google/oauth2/_client.py", line 299, in jwt_grant
    response_data = _token_endpoint_request(
                    ^^^^^^^^^^^^^^^^^^^^^^^^
  File "/home/chon/project/env/lib/python3.11/site-packages/google/oauth2/_client.py", line 270, in _token_endpoint_request
    _handle_error_response(response_data, retryable_error)
  File "/home/chon/project/env/lib/python3.11/site-packages/google/oauth2/_client.py", line 69, in _handle_error_response
    raise exceptions.RefreshError(
google.auth.exceptions.RefreshError: ('invalid_grant: Invalid JWT Signature.', {'error': 'invalid_grant', 'error_description': 'Invalid JWT Signature.'})
2025-08-24 23:37:37,796 - ERROR - AuthMetadataPluginCallback "<google.auth.transport.grpc.AuthMetadataPlugin object at 0x7fff2e3e4910>" raised exception!
Traceback (most recent call last):
  File "/home/chon/project/env/lib/python3.11/site-packages/grpc/_plugin_wrapping.py", line 105, in __call__
    self._metadata_plugin(
  File "/home/chon/project/env/lib/python3.11/site-packages/google/auth/transport/grpc.py", line 95, in __call__
    callback(self._get_authorization_headers(context), None)
             ^^^^^^^^^^^^^^^^^^^^^^^^^^^^^^^^^^^^^^^^
  File "/home/chon/project/env/lib/python3.11/site-packages/google/auth/transport/grpc.py", line 81, in _get_authorization_headers
    self._credentials.before_request(
  File "/home/chon/project/env/lib/python3.11/site-packages/google/auth/credentials.py", line 239, in before_request
    self._blocking_refresh(request)
  File "/home/chon/project/env/lib/python3.11/site-packages/google/auth/credentials.py", line 202, in _blocking_refresh
    self.refresh(request)
  File "/home/chon/project/env/lib/python3.11/site-packages/google/oauth2/service_account.py", line 448, in refresh
    access_token, expiry, _ = _client.jwt_grant(
                              ^^^^^^^^^^^^^^^^^^
  File "/home/chon/project/env/lib/python3.11/site-packages/google/oauth2/_client.py", line 299, in jwt_grant
    response_data = _token_endpoint_request(
                    ^^^^^^^^^^^^^^^^^^^^^^^^
  File "/home/chon/project/env/lib/python3.11/site-packages/google/oauth2/_client.py", line 270, in _token_endpoint_request
    _handle_error_response(response_data, retryable_error)
  File "/home/chon/project/env/lib/python3.11/site-packages/google/oauth2/_client.py", line 69, in _handle_error_response
    raise exceptions.RefreshError(
google.auth.exceptions.RefreshError: ('invalid_grant: Invalid JWT Signature.', {'error': 'invalid_grant', 'error_description': 'Invalid JWT Signature.'})
2025-08-24 23:37:38,378 - ERROR - AuthMetadataPluginCallback "<google.auth.transport.grpc.AuthMetadataPlugin object at 0x7fff2e3e4910>" raised exception!
Traceback (most recent call last):
  File "/home/chon/project/env/lib/python3.11/site-packages/grpc/_plugin_wrapping.py", line 105, in __call__
    self._metadata_plugin(
  File "/home/chon/project/env/lib/python3.11/site-packages/google/auth/transport/grpc.py", line 95, in __call__
    callback(self._get_authorization_headers(context), None)
             ^^^^^^^^^^^^^^^^^^^^^^^^^^^^^^^^^^^^^^^^
  File "/home/chon/project/env/lib/python3.11/site-packages/google/auth/transport/grpc.py", line 81, in _get_authorization_headers
    self._credentials.before_request(
  File "/home/chon/project/env/lib/python3.11/site-packages/google/auth/credentials.py", line 239, in before_request
    self._blocking_refresh(request)
  File "/home/chon/project/env/lib/python3.11/site-packages/google/auth/credentials.py", line 202, in _blocking_refresh
    self.refresh(request)
  File "/home/chon/project/env/lib/python3.11/site-packages/google/oauth2/service_account.py", line 448, in refresh
    access_token, expiry, _ = _client.jwt_grant(
                              ^^^^^^^^^^^^^^^^^^
  File "/home/chon/project/env/lib/python3.11/site-packages/google/oauth2/_client.py", line 299, in jwt_grant
    response_data = _token_endpoint_request(
                    ^^^^^^^^^^^^^^^^^^^^^^^^
  File "/home/chon/project/env/lib/python3.11/site-packages/google/oauth2/_client.py", line 270, in _token_endpoint_request
    _handle_error_response(response_data, retryable_error)
  File "/home/chon/project/env/lib/python3.11/site-packages/google/oauth2/_client.py", line 69, in _handle_error_response
    raise exceptions.RefreshError(
google.auth.exceptions.RefreshError: ('invalid_grant: Invalid JWT Signature.', {'error': 'invalid_grant', 'error_description': 'Invalid JWT Signature.'})
2025-08-24 23:37:39,066 - ERROR - AuthMetadataPluginCallback "<google.auth.transport.grpc.AuthMetadataPlugin object at 0x7fff2e3e4910>" raised exception!
Traceback (most recent call last):
  File "/home/chon/project/env/lib/python3.11/site-packages/grpc/_plugin_wrapping.py", line 105, in __call__
    self._metadata_plugin(
  File "/home/chon/project/env/lib/python3.11/site-packages/google/auth/transport/grpc.py", line 95, in __call__
    callback(self._get_authorization_headers(context), None)
             ^^^^^^^^^^^^^^^^^^^^^^^^^^^^^^^^^^^^^^^^
  File "/home/chon/project/env/lib/python3.11/site-packages/google/auth/transport/grpc.py", line 81, in _get_authorization_headers
    self._credentials.before_request(
  File "/home/chon/project/env/lib/python3.11/site-packages/google/auth/credentials.py", line 239, in before_request
    self._blocking_refresh(request)
  File "/home/chon/project/env/lib/python3.11/site-packages/google/auth/credentials.py", line 202, in _blocking_refresh
    self.refresh(request)
  File "/home/chon/project/env/lib/python3.11/site-packages/google/oauth2/service_account.py", line 448, in refresh
    access_token, expiry, _ = _client.jwt_grant(
                              ^^^^^^^^^^^^^^^^^^
  File "/home/chon/project/env/lib/python3.11/site-packages/google/oauth2/_client.py", line 299, in jwt_grant
    response_data = _token_endpoint_request(
                    ^^^^^^^^^^^^^^^^^^^^^^^^
  File "/home/chon/project/env/lib/python3.11/site-packages/google/oauth2/_client.py", line 270, in _token_endpoint_request
    _handle_error_response(response_data, retryable_error)
  File "/home/chon/project/env/lib/python3.11/site-packages/google/oauth2/_client.py", line 69, in _handle_error_response
    raise exceptions.RefreshError(
google.auth.exceptions.RefreshError: ('invalid_grant: Invalid JWT Signature.', {'error': 'invalid_grant', 'error_description': 'Invalid JWT Signature.'})
2025-08-24 23:37:39,930 - ERROR - AuthMetadataPluginCallback "<google.auth.transport.grpc.AuthMetadataPlugin object at 0x7fff2e3e4910>" raised exception!
Traceback (most recent call last):
  File "/home/chon/project/env/lib/python3.11/site-packages/grpc/_plugin_wrapping.py", line 105, in __call__
    self._metadata_plugin(
  File "/home/chon/project/env/lib/python3.11/site-packages/google/auth/transport/grpc.py", line 95, in __call__
    callback(self._get_authorization_headers(context), None)
             ^^^^^^^^^^^^^^^^^^^^^^^^^^^^^^^^^^^^^^^^
  File "/home/chon/project/env/lib/python3.11/site-packages/google/auth/transport/grpc.py", line 81, in _get_authorization_headers
    self._credentials.before_request(
  File "/home/chon/project/env/lib/python3.11/site-packages/google/auth/credentials.py", line 239, in before_request
    self._blocking_refresh(request)
  File "/home/chon/project/env/lib/python3.11/site-packages/google/auth/credentials.py", line 202, in _blocking_refresh
    self.refresh(request)
  File "/home/chon/project/env/lib/python3.11/site-packages/google/oauth2/service_account.py", line 448, in refresh
    access_token, expiry, _ = _client.jwt_grant(
                              ^^^^^^^^^^^^^^^^^^
  File "/home/chon/project/env/lib/python3.11/site-packages/google/oauth2/_client.py", line 299, in jwt_grant
    response_data = _token_endpoint_request(
                    ^^^^^^^^^^^^^^^^^^^^^^^^
  File "/home/chon/project/env/lib/python3.11/site-packages/google/oauth2/_client.py", line 270, in _token_endpoint_request
    _handle_error_response(response_data, retryable_error)
  File "/home/chon/project/env/lib/python3.11/site-packages/google/oauth2/_client.py", line 69, in _handle_error_response
    raise exceptions.RefreshError(
google.auth.exceptions.RefreshError: ('invalid_grant: Invalid JWT Signature.', {'error': 'invalid_grant', 'error_description': 'Invalid JWT Signature.'})
2025-08-24 23:37:40,020 - ERROR - AuthMetadataPluginCallback "<google.auth.transport.grpc.AuthMetadataPlugin object at 0x7fff2e3e4910>" raised exception!
Traceback (most recent call last):
  File "/home/chon/project/env/lib/python3.11/site-packages/grpc/_plugin_wrapping.py", line 105, in __call__
    self._metadata_plugin(
  File "/home/chon/project/env/lib/python3.11/site-packages/google/auth/transport/grpc.py", line 95, in __call__
    callback(self._get_authorization_headers(context), None)
             ^^^^^^^^^^^^^^^^^^^^^^^^^^^^^^^^^^^^^^^^
  File "/home/chon/project/env/lib/python3.11/site-packages/google/auth/transport/grpc.py", line 81, in _get_authorization_headers
    self._credentials.before_request(
  File "/home/chon/project/env/lib/python3.11/site-packages/google/auth/credentials.py", line 239, in before_request
    self._blocking_refresh(request)
  File "/home/chon/project/env/lib/python3.11/site-packages/google/auth/credentials.py", line 202, in _blocking_refresh
    self.refresh(request)
  File "/home/chon/project/env/lib/python3.11/site-packages/google/oauth2/service_account.py", line 448, in refresh
    access_token, expiry, _ = _client.jwt_grant(
                              ^^^^^^^^^^^^^^^^^^
  File "/home/chon/project/env/lib/python3.11/site-packages/google/oauth2/_client.py", line 299, in jwt_grant
    response_data = _token_endpoint_request(
                    ^^^^^^^^^^^^^^^^^^^^^^^^
  File "/home/chon/project/env/lib/python3.11/site-packages/google/oauth2/_client.py", line 270, in _token_endpoint_request
    _handle_error_response(response_data, retryable_error)
  File "/home/chon/project/env/lib/python3.11/site-packages/google/oauth2/_client.py", line 69, in _handle_error_response
    raise exceptions.RefreshError(
google.auth.exceptions.RefreshError: ('invalid_grant: Invalid JWT Signature.', {'error': 'invalid_grant', 'error_description': 'Invalid JWT Signature.'})
2025-08-24 23:37:40,523 - ERROR - AuthMetadataPluginCallback "<google.auth.transport.grpc.AuthMetadataPlugin object at 0x7fff2e3e4910>" raised exception!
Traceback (most recent call last):
  File "/home/chon/project/env/lib/python3.11/site-packages/grpc/_plugin_wrapping.py", line 105, in __call__
    self._metadata_plugin(
  File "/home/chon/project/env/lib/python3.11/site-packages/google/auth/transport/grpc.py", line 95, in __call__
    callback(self._get_authorization_headers(context), None)
             ^^^^^^^^^^^^^^^^^^^^^^^^^^^^^^^^^^^^^^^^
  File "/home/chon/project/env/lib/python3.11/site-packages/google/auth/transport/grpc.py", line 81, in _get_authorization_headers
    self._credentials.before_request(
  File "/home/chon/project/env/lib/python3.11/site-packages/google/auth/credentials.py", line 239, in before_request
    self._blocking_refresh(request)
  File "/home/chon/project/env/lib/python3.11/site-packages/google/auth/credentials.py", line 202, in _blocking_refresh
    self.refresh(request)
  File "/home/chon/project/env/lib/python3.11/site-packages/google/oauth2/service_account.py", line 448, in refresh
    access_token, expiry, _ = _client.jwt_grant(
                              ^^^^^^^^^^^^^^^^^^
  File "/home/chon/project/env/lib/python3.11/site-packages/google/oauth2/_client.py", line 299, in jwt_grant
    response_data = _token_endpoint_request(
                    ^^^^^^^^^^^^^^^^^^^^^^^^
  File "/home/chon/project/env/lib/python3.11/site-packages/google/oauth2/_client.py", line 270, in _token_endpoint_request
    _handle_error_response(response_data, retryable_error)
  File "/home/chon/project/env/lib/python3.11/site-packages/google/oauth2/_client.py", line 69, in _handle_error_response
    raise exceptions.RefreshError(
google.auth.exceptions.RefreshError: ('invalid_grant: Invalid JWT Signature.', {'error': 'invalid_grant', 'error_description': 'Invalid JWT Signature.'})
2025-08-24 23:37:40,601 - ERROR - AuthMetadataPluginCallback "<google.auth.transport.grpc.AuthMetadataPlugin object at 0x7fff2e3e4910>" raised exception!
Traceback (most recent call last):
  File "/home/chon/project/env/lib/python3.11/site-packages/grpc/_plugin_wrapping.py", line 105, in __call__
    self._metadata_plugin(
  File "/home/chon/project/env/lib/python3.11/site-packages/google/auth/transport/grpc.py", line 95, in __call__
    callback(self._get_authorization_headers(context), None)
             ^^^^^^^^^^^^^^^^^^^^^^^^^^^^^^^^^^^^^^^^
  File "/home/chon/project/env/lib/python3.11/site-packages/google/auth/transport/grpc.py", line 81, in _get_authorization_headers
    self._credentials.before_request(
  File "/home/chon/project/env/lib/python3.11/site-packages/google/auth/credentials.py", line 239, in before_request
    self._blocking_refresh(request)
  File "/home/chon/project/env/lib/python3.11/site-packages/google/auth/credentials.py", line 202, in _blocking_refresh
    self.refresh(request)
  File "/home/chon/project/env/lib/python3.11/site-packages/google/oauth2/service_account.py", line 448, in refresh
    access_token, expiry, _ = _client.jwt_grant(
                              ^^^^^^^^^^^^^^^^^^
  File "/home/chon/project/env/lib/python3.11/site-packages/google/oauth2/_client.py", line 299, in jwt_grant
    response_data = _token_endpoint_request(
                    ^^^^^^^^^^^^^^^^^^^^^^^^
  File "/home/chon/project/env/lib/python3.11/site-packages/google/oauth2/_client.py", line 270, in _token_endpoint_request
    _handle_error_response(response_data, retryable_error)
  File "/home/chon/project/env/lib/python3.11/site-packages/google/oauth2/_client.py", line 69, in _handle_error_response
    raise exceptions.RefreshError(
google.auth.exceptions.RefreshError: ('invalid_grant: Invalid JWT Signature.', {'error': 'invalid_grant', 'error_description': 'Invalid JWT Signature.'})
2025-08-24 23:37:41,550 - ERROR - AuthMetadataPluginCallback "<google.auth.transport.grpc.AuthMetadataPlugin object at 0x7fff2e3e4910>" raised exception!
Traceback (most recent call last):
  File "/home/chon/project/env/lib/python3.11/site-packages/grpc/_plugin_wrapping.py", line 105, in __call__
    self._metadata_plugin(
  File "/home/chon/project/env/lib/python3.11/site-packages/google/auth/transport/grpc.py", line 95, in __call__
    callback(self._get_authorization_headers(context), None)
             ^^^^^^^^^^^^^^^^^^^^^^^^^^^^^^^^^^^^^^^^
  File "/home/chon/project/env/lib/python3.11/site-packages/google/auth/transport/grpc.py", line 81, in _get_authorization_headers
    self._credentials.before_request(
  File "/home/chon/project/env/lib/python3.11/site-packages/google/auth/credentials.py", line 239, in before_request
    self._blocking_refresh(request)
  File "/home/chon/project/env/lib/python3.11/site-packages/google/auth/credentials.py", line 202, in _blocking_refresh
    self.refresh(request)
  File "/home/chon/project/env/lib/python3.11/site-packages/google/oauth2/service_account.py", line 448, in refresh
    access_token, expiry, _ = _client.jwt_grant(
                              ^^^^^^^^^^^^^^^^^^
  File "/home/chon/project/env/lib/python3.11/site-packages/google/oauth2/_client.py", line 299, in jwt_grant
    response_data = _token_endpoint_request(
                    ^^^^^^^^^^^^^^^^^^^^^^^^
  File "/home/chon/project/env/lib/python3.11/site-packages/google/oauth2/_client.py", line 270, in _token_endpoint_request
    _handle_error_response(response_data, retryable_error)
  File "/home/chon/project/env/lib/python3.11/site-packages/google/oauth2/_client.py", line 69, in _handle_error_response
    raise exceptions.RefreshError(
google.auth.exceptions.RefreshError: ('invalid_grant: Invalid JWT Signature.', {'error': 'invalid_grant', 'error_description': 'Invalid JWT Signature.'})
2025-08-24 23:37:42,925 - ERROR - AuthMetadataPluginCallback "<google.auth.transport.grpc.AuthMetadataPlugin object at 0x7fff2e3e4910>" raised exception!
Traceback (most recent call last):
  File "/home/chon/project/env/lib/python3.11/site-packages/grpc/_plugin_wrapping.py", line 105, in __call__
    self._metadata_plugin(
  File "/home/chon/project/env/lib/python3.11/site-packages/google/auth/transport/grpc.py", line 95, in __call__
    callback(self._get_authorization_headers(context), None)
             ^^^^^^^^^^^^^^^^^^^^^^^^^^^^^^^^^^^^^^^^
  File "/home/chon/project/env/lib/python3.11/site-packages/google/auth/transport/grpc.py", line 81, in _get_authorization_headers
    self._credentials.before_request(
  File "/home/chon/project/env/lib/python3.11/site-packages/google/auth/credentials.py", line 239, in before_request
    self._blocking_refresh(request)
  File "/home/chon/project/env/lib/python3.11/site-packages/google/auth/credentials.py", line 202, in _blocking_refresh
    self.refresh(request)
  File "/home/chon/project/env/lib/python3.11/site-packages/google/oauth2/service_account.py", line 448, in refresh
    access_token, expiry, _ = _client.jwt_grant(
                              ^^^^^^^^^^^^^^^^^^
  File "/home/chon/project/env/lib/python3.11/site-packages/google/oauth2/_client.py", line 299, in jwt_grant
    response_data = _token_endpoint_request(
                    ^^^^^^^^^^^^^^^^^^^^^^^^
  File "/home/chon/project/env/lib/python3.11/site-packages/google/oauth2/_client.py", line 270, in _token_endpoint_request
    _handle_error_response(response_data, retryable_error)
  File "/home/chon/project/env/lib/python3.11/site-packages/google/oauth2/_client.py", line 69, in _handle_error_response
    raise exceptions.RefreshError(
google.auth.exceptions.RefreshError: ('invalid_grant: Invalid JWT Signature.', {'error': 'invalid_grant', 'error_description': 'Invalid JWT Signature.'})
2025-08-24 23:37:46,356 - ERROR - AuthMetadataPluginCallback "<google.auth.transport.grpc.AuthMetadataPlugin object at 0x7fff2e3e4910>" raised exception!
Traceback (most recent call last):
  File "/home/chon/project/env/lib/python3.11/site-packages/grpc/_plugin_wrapping.py", line 105, in __call__
    self._metadata_plugin(
  File "/home/chon/project/env/lib/python3.11/site-packages/google/auth/transport/grpc.py", line 95, in __call__
    callback(self._get_authorization_headers(context), None)
             ^^^^^^^^^^^^^^^^^^^^^^^^^^^^^^^^^^^^^^^^
  File "/home/chon/project/env/lib/python3.11/site-packages/google/auth/transport/grpc.py", line 81, in _get_authorization_headers
    self._credentials.before_request(
  File "/home/chon/project/env/lib/python3.11/site-packages/google/auth/credentials.py", line 239, in before_request
    self._blocking_refresh(request)
  File "/home/chon/project/env/lib/python3.11/site-packages/google/auth/credentials.py", line 202, in _blocking_refresh
    self.refresh(request)
  File "/home/chon/project/env/lib/python3.11/site-packages/google/oauth2/service_account.py", line 448, in refresh
    access_token, expiry, _ = _client.jwt_grant(
                              ^^^^^^^^^^^^^^^^^^
  File "/home/chon/project/env/lib/python3.11/site-packages/google/oauth2/_client.py", line 299, in jwt_grant
    response_data = _token_endpoint_request(
                    ^^^^^^^^^^^^^^^^^^^^^^^^
  File "/home/chon/project/env/lib/python3.11/site-packages/google/oauth2/_client.py", line 270, in _token_endpoint_request
    _handle_error_response(response_data, retryable_error)
  File "/home/chon/project/env/lib/python3.11/site-packages/google/oauth2/_client.py", line 69, in _handle_error_response
    raise exceptions.RefreshError(
google.auth.exceptions.RefreshError: ('invalid_grant: Invalid JWT Signature.', {'error': 'invalid_grant', 'error_description': 'Invalid JWT Signature.'})
2025-08-24 23:37:46,455 - ERROR - AuthMetadataPluginCallback "<google.auth.transport.grpc.AuthMetadataPlugin object at 0x7fff2e3e4910>" raised exception!
Traceback (most recent call last):
  File "/home/chon/project/env/lib/python3.11/site-packages/grpc/_plugin_wrapping.py", line 105, in __call__
    self._metadata_plugin(
  File "/home/chon/project/env/lib/python3.11/site-packages/google/auth/transport/grpc.py", line 95, in __call__
    callback(self._get_authorization_headers(context), None)
             ^^^^^^^^^^^^^^^^^^^^^^^^^^^^^^^^^^^^^^^^
  File "/home/chon/project/env/lib/python3.11/site-packages/google/auth/transport/grpc.py", line 81, in _get_authorization_headers
    self._credentials.before_request(
  File "/home/chon/project/env/lib/python3.11/site-packages/google/auth/credentials.py", line 239, in before_request
    self._blocking_refresh(request)
  File "/home/chon/project/env/lib/python3.11/site-packages/google/auth/credentials.py", line 202, in _blocking_refresh
    self.refresh(request)
  File "/home/chon/project/env/lib/python3.11/site-packages/google/oauth2/service_account.py", line 448, in refresh
    access_token, expiry, _ = _client.jwt_grant(
                              ^^^^^^^^^^^^^^^^^^
  File "/home/chon/project/env/lib/python3.11/site-packages/google/oauth2/_client.py", line 299, in jwt_grant
    response_data = _token_endpoint_request(
                    ^^^^^^^^^^^^^^^^^^^^^^^^
  File "/home/chon/project/env/lib/python3.11/site-packages/google/oauth2/_client.py", line 270, in _token_endpoint_request
    _handle_error_response(response_data, retryable_error)
  File "/home/chon/project/env/lib/python3.11/site-packages/google/oauth2/_client.py", line 69, in _handle_error_response
    raise exceptions.RefreshError(
google.auth.exceptions.RefreshError: ('invalid_grant: Invalid JWT Signature.', {'error': 'invalid_grant', 'error_description': 'Invalid JWT Signature.'})
2025-08-24 23:37:46,530 - ERROR - AuthMetadataPluginCallback "<google.auth.transport.grpc.AuthMetadataPlugin object at 0x7fff2e3e4910>" raised exception!
Traceback (most recent call last):
  File "/home/chon/project/env/lib/python3.11/site-packages/grpc/_plugin_wrapping.py", line 105, in __call__
    self._metadata_plugin(
  File "/home/chon/project/env/lib/python3.11/site-packages/google/auth/transport/grpc.py", line 95, in __call__
    callback(self._get_authorization_headers(context), None)
             ^^^^^^^^^^^^^^^^^^^^^^^^^^^^^^^^^^^^^^^^
  File "/home/chon/project/env/lib/python3.11/site-packages/google/auth/transport/grpc.py", line 81, in _get_authorization_headers
    self._credentials.before_request(
  File "/home/chon/project/env/lib/python3.11/site-packages/google/auth/credentials.py", line 239, in before_request
    self._blocking_refresh(request)
  File "/home/chon/project/env/lib/python3.11/site-packages/google/auth/credentials.py", line 202, in _blocking_refresh
    self.refresh(request)
  File "/home/chon/project/env/lib/python3.11/site-packages/google/oauth2/service_account.py", line 448, in refresh
    access_token, expiry, _ = _client.jwt_grant(
                              ^^^^^^^^^^^^^^^^^^
  File "/home/chon/project/env/lib/python3.11/site-packages/google/oauth2/_client.py", line 299, in jwt_grant
    response_data = _token_endpoint_request(
                    ^^^^^^^^^^^^^^^^^^^^^^^^
  File "/home/chon/project/env/lib/python3.11/site-packages/google/oauth2/_client.py", line 270, in _token_endpoint_request
    _handle_error_response(response_data, retryable_error)
  File "/home/chon/project/env/lib/python3.11/site-packages/google/oauth2/_client.py", line 69, in _handle_error_response
    raise exceptions.RefreshError(
google.auth.exceptions.RefreshError: ('invalid_grant: Invalid JWT Signature.', {'error': 'invalid_grant', 'error_description': 'Invalid JWT Signature.'})
2025-08-24 23:37:46,611 - ERROR - AuthMetadataPluginCallback "<google.auth.transport.grpc.AuthMetadataPlugin object at 0x7fff2e3e4910>" raised exception!
Traceback (most recent call last):
  File "/home/chon/project/env/lib/python3.11/site-packages/grpc/_plugin_wrapping.py", line 105, in __call__
    self._metadata_plugin(
  File "/home/chon/project/env/lib/python3.11/site-packages/google/auth/transport/grpc.py", line 95, in __call__
    callback(self._get_authorization_headers(context), None)
             ^^^^^^^^^^^^^^^^^^^^^^^^^^^^^^^^^^^^^^^^
  File "/home/chon/project/env/lib/python3.11/site-packages/google/auth/transport/grpc.py", line 81, in _get_authorization_headers
    self._credentials.before_request(
  File "/home/chon/project/env/lib/python3.11/site-packages/google/auth/credentials.py", line 239, in before_request
    self._blocking_refresh(request)
  File "/home/chon/project/env/lib/python3.11/site-packages/google/auth/credentials.py", line 202, in _blocking_refresh
    self.refresh(request)
  File "/home/chon/project/env/lib/python3.11/site-packages/google/oauth2/service_account.py", line 448, in refresh
    access_token, expiry, _ = _client.jwt_grant(
                              ^^^^^^^^^^^^^^^^^^
  File "/home/chon/project/env/lib/python3.11/site-packages/google/oauth2/_client.py", line 299, in jwt_grant
    response_data = _token_endpoint_request(
                    ^^^^^^^^^^^^^^^^^^^^^^^^
  File "/home/chon/project/env/lib/python3.11/site-packages/google/oauth2/_client.py", line 270, in _token_endpoint_request
    _handle_error_response(response_data, retryable_error)
  File "/home/chon/project/env/lib/python3.11/site-packages/google/oauth2/_client.py", line 69, in _handle_error_response
    raise exceptions.RefreshError(
google.auth.exceptions.RefreshError: ('invalid_grant: Invalid JWT Signature.', {'error': 'invalid_grant', 'error_description': 'Invalid JWT Signature.'})
2025-08-24 23:37:46,749 - ERROR - AuthMetadataPluginCallback "<google.auth.transport.grpc.AuthMetadataPlugin object at 0x7fff2e3e4910>" raised exception!
Traceback (most recent call last):
  File "/home/chon/project/env/lib/python3.11/site-packages/grpc/_plugin_wrapping.py", line 105, in __call__
    self._metadata_plugin(
  File "/home/chon/project/env/lib/python3.11/site-packages/google/auth/transport/grpc.py", line 95, in __call__
    callback(self._get_authorization_headers(context), None)
             ^^^^^^^^^^^^^^^^^^^^^^^^^^^^^^^^^^^^^^^^
  File "/home/chon/project/env/lib/python3.11/site-packages/google/auth/transport/grpc.py", line 81, in _get_authorization_headers
    self._credentials.before_request(
  File "/home/chon/project/env/lib/python3.11/site-packages/google/auth/credentials.py", line 239, in before_request
    self._blocking_refresh(request)
  File "/home/chon/project/env/lib/python3.11/site-packages/google/auth/credentials.py", line 202, in _blocking_refresh
    self.refresh(request)
  File "/home/chon/project/env/lib/python3.11/site-packages/google/oauth2/service_account.py", line 448, in refresh
    access_token, expiry, _ = _client.jwt_grant(
                              ^^^^^^^^^^^^^^^^^^
  File "/home/chon/project/env/lib/python3.11/site-packages/google/oauth2/_client.py", line 299, in jwt_grant
    response_data = _token_endpoint_request(
                    ^^^^^^^^^^^^^^^^^^^^^^^^
  File "/home/chon/project/env/lib/python3.11/site-packages/google/oauth2/_client.py", line 270, in _token_endpoint_request
    _handle_error_response(response_data, retryable_error)
  File "/home/chon/project/env/lib/python3.11/site-packages/google/oauth2/_client.py", line 69, in _handle_error_response
    raise exceptions.RefreshError(
google.auth.exceptions.RefreshError: ('invalid_grant: Invalid JWT Signature.', {'error': 'invalid_grant', 'error_description': 'Invalid JWT Signature.'})
2025-08-24 23:37:46,861 - ERROR - AuthMetadataPluginCallback "<google.auth.transport.grpc.AuthMetadataPlugin object at 0x7fff2e3e4910>" raised exception!
Traceback (most recent call last):
  File "/home/chon/project/env/lib/python3.11/site-packages/grpc/_plugin_wrapping.py", line 105, in __call__
    self._metadata_plugin(
  File "/home/chon/project/env/lib/python3.11/site-packages/google/auth/transport/grpc.py", line 95, in __call__
    callback(self._get_authorization_headers(context), None)
             ^^^^^^^^^^^^^^^^^^^^^^^^^^^^^^^^^^^^^^^^
  File "/home/chon/project/env/lib/python3.11/site-packages/google/auth/transport/grpc.py", line 81, in _get_authorization_headers
    self._credentials.before_request(
  File "/home/chon/project/env/lib/python3.11/site-packages/google/auth/credentials.py", line 239, in before_request
    self._blocking_refresh(request)
  File "/home/chon/project/env/lib/python3.11/site-packages/google/auth/credentials.py", line 202, in _blocking_refresh
    self.refresh(request)
  File "/home/chon/project/env/lib/python3.11/site-packages/google/oauth2/service_account.py", line 448, in refresh
    access_token, expiry, _ = _client.jwt_grant(
                              ^^^^^^^^^^^^^^^^^^
  File "/home/chon/project/env/lib/python3.11/site-packages/google/oauth2/_client.py", line 299, in jwt_grant
    response_data = _token_endpoint_request(
                    ^^^^^^^^^^^^^^^^^^^^^^^^
  File "/home/chon/project/env/lib/python3.11/site-packages/google/oauth2/_client.py", line 270, in _token_endpoint_request
    _handle_error_response(response_data, retryable_error)
  File "/home/chon/project/env/lib/python3.11/site-packages/google/oauth2/_client.py", line 69, in _handle_error_response
    raise exceptions.RefreshError(
google.auth.exceptions.RefreshError: ('invalid_grant: Invalid JWT Signature.', {'error': 'invalid_grant', 'error_description': 'Invalid JWT Signature.'})
2025-08-24 23:37:47,201 - ERROR - AuthMetadataPluginCallback "<google.auth.transport.grpc.AuthMetadataPlugin object at 0x7fff2e3e4910>" raised exception!
Traceback (most recent call last):
  File "/home/chon/project/env/lib/python3.11/site-packages/grpc/_plugin_wrapping.py", line 105, in __call__
    self._metadata_plugin(
  File "/home/chon/project/env/lib/python3.11/site-packages/google/auth/transport/grpc.py", line 95, in __call__
    callback(self._get_authorization_headers(context), None)
             ^^^^^^^^^^^^^^^^^^^^^^^^^^^^^^^^^^^^^^^^
  File "/home/chon/project/env/lib/python3.11/site-packages/google/auth/transport/grpc.py", line 81, in _get_authorization_headers
    self._credentials.before_request(
  File "/home/chon/project/env/lib/python3.11/site-packages/google/auth/credentials.py", line 239, in before_request
    self._blocking_refresh(request)
  File "/home/chon/project/env/lib/python3.11/site-packages/google/auth/credentials.py", line 202, in _blocking_refresh
    self.refresh(request)
  File "/home/chon/project/env/lib/python3.11/site-packages/google/oauth2/service_account.py", line 448, in refresh
    access_token, expiry, _ = _client.jwt_grant(
                              ^^^^^^^^^^^^^^^^^^
  File "/home/chon/project/env/lib/python3.11/site-packages/google/oauth2/_client.py", line 299, in jwt_grant
    response_data = _token_endpoint_request(
                    ^^^^^^^^^^^^^^^^^^^^^^^^
  File "/home/chon/project/env/lib/python3.11/site-packages/google/oauth2/_client.py", line 270, in _token_endpoint_request
    _handle_error_response(response_data, retryable_error)
  File "/home/chon/project/env/lib/python3.11/site-packages/google/oauth2/_client.py", line 69, in _handle_error_response
    raise exceptions.RefreshError(
google.auth.exceptions.RefreshError: ('invalid_grant: Invalid JWT Signature.', {'error': 'invalid_grant', 'error_description': 'Invalid JWT Signature.'})
2025-08-24 23:37:47,352 - ERROR - AuthMetadataPluginCallback "<google.auth.transport.grpc.AuthMetadataPlugin object at 0x7fff2e3e4910>" raised exception!
Traceback (most recent call last):
  File "/home/chon/project/env/lib/python3.11/site-packages/grpc/_plugin_wrapping.py", line 105, in __call__
    self._metadata_plugin(
  File "/home/chon/project/env/lib/python3.11/site-packages/google/auth/transport/grpc.py", line 95, in __call__
    callback(self._get_authorization_headers(context), None)
             ^^^^^^^^^^^^^^^^^^^^^^^^^^^^^^^^^^^^^^^^
  File "/home/chon/project/env/lib/python3.11/site-packages/google/auth/transport/grpc.py", line 81, in _get_authorization_headers
    self._credentials.before_request(
  File "/home/chon/project/env/lib/python3.11/site-packages/google/auth/credentials.py", line 239, in before_request
    self._blocking_refresh(request)
  File "/home/chon/project/env/lib/python3.11/site-packages/google/auth/credentials.py", line 202, in _blocking_refresh
    self.refresh(request)
  File "/home/chon/project/env/lib/python3.11/site-packages/google/oauth2/service_account.py", line 448, in refresh
    access_token, expiry, _ = _client.jwt_grant(
                              ^^^^^^^^^^^^^^^^^^
  File "/home/chon/project/env/lib/python3.11/site-packages/google/oauth2/_client.py", line 299, in jwt_grant
    response_data = _token_endpoint_request(
                    ^^^^^^^^^^^^^^^^^^^^^^^^
  File "/home/chon/project/env/lib/python3.11/site-packages/google/oauth2/_client.py", line 270, in _token_endpoint_request
    _handle_error_response(response_data, retryable_error)
  File "/home/chon/project/env/lib/python3.11/site-packages/google/oauth2/_client.py", line 69, in _handle_error_response
    raise exceptions.RefreshError(
google.auth.exceptions.RefreshError: ('invalid_grant: Invalid JWT Signature.', {'error': 'invalid_grant', 'error_description': 'Invalid JWT Signature.'})
2025-08-24 23:37:47,499 - ERROR - AuthMetadataPluginCallback "<google.auth.transport.grpc.AuthMetadataPlugin object at 0x7fff2e3e4910>" raised exception!
Traceback (most recent call last):
  File "/home/chon/project/env/lib/python3.11/site-packages/grpc/_plugin_wrapping.py", line 105, in __call__
    self._metadata_plugin(
  File "/home/chon/project/env/lib/python3.11/site-packages/google/auth/transport/grpc.py", line 95, in __call__
    callback(self._get_authorization_headers(context), None)
             ^^^^^^^^^^^^^^^^^^^^^^^^^^^^^^^^^^^^^^^^
  File "/home/chon/project/env/lib/python3.11/site-packages/google/auth/transport/grpc.py", line 81, in _get_authorization_headers
    self._credentials.before_request(
  File "/home/chon/project/env/lib/python3.11/site-packages/google/auth/credentials.py", line 239, in before_request
    self._blocking_refresh(request)
  File "/home/chon/project/env/lib/python3.11/site-packages/google/auth/credentials.py", line 202, in _blocking_refresh
    self.refresh(request)
  File "/home/chon/project/env/lib/python3.11/site-packages/google/oauth2/service_account.py", line 448, in refresh
    access_token, expiry, _ = _client.jwt_grant(
                              ^^^^^^^^^^^^^^^^^^
  File "/home/chon/project/env/lib/python3.11/site-packages/google/oauth2/_client.py", line 299, in jwt_grant
    response_data = _token_endpoint_request(
                    ^^^^^^^^^^^^^^^^^^^^^^^^
  File "/home/chon/project/env/lib/python3.11/site-packages/google/oauth2/_client.py", line 270, in _token_endpoint_request
    _handle_error_response(response_data, retryable_error)
  File "/home/chon/project/env/lib/python3.11/site-packages/google/oauth2/_client.py", line 69, in _handle_error_response
    raise exceptions.RefreshError(
google.auth.exceptions.RefreshError: ('invalid_grant: Invalid JWT Signature.', {'error': 'invalid_grant', 'error_description': 'Invalid JWT Signature.'})
2025-08-25 00:09:22,208 - INFO - Firestore sink enabled (collection='pm_readings', batch=50, flush=30s)
2025-08-25 00:09:22,208 - INFO - Program started.
2025-08-25 00:09:22,410 - INFO - Sensor OK: Indoor=(5.0, 9.0, 9.0), Outdoor=(5.0, 8.0, 8.0)
2025-08-25 00:09:32,410 - INFO - Sensor OK: Indoor=(5.0, 9.0, 9.0), Outdoor=(5.0, 7.0, 7.0)
2025-08-25 00:09:42,411 - INFO - Sensor OK: Indoor=(5.0, 8.0, 8.0), Outdoor=(4.0, 6.0, 6.0)
2025-08-25 00:09:52,414 - INFO - Sensor OK: Indoor=(5.0, 8.0, 8.0), Outdoor=(4.0, 6.0, 6.0)
2025-08-25 00:09:52,790 - ERROR - AuthMetadataPluginCallback "<google.auth.transport.grpc.AuthMetadataPlugin object at 0x7ffef9bf4fd0>" raised exception!
Traceback (most recent call last):
  File "/home/chon/project/env/lib/python3.11/site-packages/grpc/_plugin_wrapping.py", line 105, in __call__
    self._metadata_plugin(
  File "/home/chon/project/env/lib/python3.11/site-packages/google/auth/transport/grpc.py", line 95, in __call__
    callback(self._get_authorization_headers(context), None)
             ^^^^^^^^^^^^^^^^^^^^^^^^^^^^^^^^^^^^^^^^
  File "/home/chon/project/env/lib/python3.11/site-packages/google/auth/transport/grpc.py", line 81, in _get_authorization_headers
    self._credentials.before_request(
  File "/home/chon/project/env/lib/python3.11/site-packages/google/auth/credentials.py", line 239, in before_request
    self._blocking_refresh(request)
  File "/home/chon/project/env/lib/python3.11/site-packages/google/auth/credentials.py", line 202, in _blocking_refresh
    self.refresh(request)
  File "/home/chon/project/env/lib/python3.11/site-packages/google/oauth2/service_account.py", line 448, in refresh
    access_token, expiry, _ = _client.jwt_grant(
                              ^^^^^^^^^^^^^^^^^^
  File "/home/chon/project/env/lib/python3.11/site-packages/google/oauth2/_client.py", line 299, in jwt_grant
    response_data = _token_endpoint_request(
                    ^^^^^^^^^^^^^^^^^^^^^^^^
  File "/home/chon/project/env/lib/python3.11/site-packages/google/oauth2/_client.py", line 270, in _token_endpoint_request
    _handle_error_response(response_data, retryable_error)
  File "/home/chon/project/env/lib/python3.11/site-packages/google/oauth2/_client.py", line 69, in _handle_error_response
    raise exceptions.RefreshError(
google.auth.exceptions.RefreshError: ('invalid_grant: Invalid JWT Signature.', {'error': 'invalid_grant', 'error_description': 'Invalid JWT Signature.'})
2025-08-25 00:09:52,924 - ERROR - AuthMetadataPluginCallback "<google.auth.transport.grpc.AuthMetadataPlugin object at 0x7ffef9bf4fd0>" raised exception!
Traceback (most recent call last):
  File "/home/chon/project/env/lib/python3.11/site-packages/grpc/_plugin_wrapping.py", line 105, in __call__
    self._metadata_plugin(
  File "/home/chon/project/env/lib/python3.11/site-packages/google/auth/transport/grpc.py", line 95, in __call__
    callback(self._get_authorization_headers(context), None)
             ^^^^^^^^^^^^^^^^^^^^^^^^^^^^^^^^^^^^^^^^
  File "/home/chon/project/env/lib/python3.11/site-packages/google/auth/transport/grpc.py", line 81, in _get_authorization_headers
    self._credentials.before_request(
  File "/home/chon/project/env/lib/python3.11/site-packages/google/auth/credentials.py", line 239, in before_request
    self._blocking_refresh(request)
  File "/home/chon/project/env/lib/python3.11/site-packages/google/auth/credentials.py", line 202, in _blocking_refresh
    self.refresh(request)
  File "/home/chon/project/env/lib/python3.11/site-packages/google/oauth2/service_account.py", line 448, in refresh
    access_token, expiry, _ = _client.jwt_grant(
                              ^^^^^^^^^^^^^^^^^^
  File "/home/chon/project/env/lib/python3.11/site-packages/google/oauth2/_client.py", line 299, in jwt_grant
    response_data = _token_endpoint_request(
                    ^^^^^^^^^^^^^^^^^^^^^^^^
  File "/home/chon/project/env/lib/python3.11/site-packages/google/oauth2/_client.py", line 270, in _token_endpoint_request
    _handle_error_response(response_data, retryable_error)
  File "/home/chon/project/env/lib/python3.11/site-packages/google/oauth2/_client.py", line 69, in _handle_error_response
    raise exceptions.RefreshError(
google.auth.exceptions.RefreshError: ('invalid_grant: Invalid JWT Signature.', {'error': 'invalid_grant', 'error_description': 'Invalid JWT Signature.'})
2025-08-25 00:09:52,998 - ERROR - AuthMetadataPluginCallback "<google.auth.transport.grpc.AuthMetadataPlugin object at 0x7ffef9bf4fd0>" raised exception!
Traceback (most recent call last):
  File "/home/chon/project/env/lib/python3.11/site-packages/grpc/_plugin_wrapping.py", line 105, in __call__
    self._metadata_plugin(
  File "/home/chon/project/env/lib/python3.11/site-packages/google/auth/transport/grpc.py", line 95, in __call__
    callback(self._get_authorization_headers(context), None)
             ^^^^^^^^^^^^^^^^^^^^^^^^^^^^^^^^^^^^^^^^
  File "/home/chon/project/env/lib/python3.11/site-packages/google/auth/transport/grpc.py", line 81, in _get_authorization_headers
    self._credentials.before_request(
  File "/home/chon/project/env/lib/python3.11/site-packages/google/auth/credentials.py", line 239, in before_request
    self._blocking_refresh(request)
  File "/home/chon/project/env/lib/python3.11/site-packages/google/auth/credentials.py", line 202, in _blocking_refresh
    self.refresh(request)
  File "/home/chon/project/env/lib/python3.11/site-packages/google/oauth2/service_account.py", line 448, in refresh
    access_token, expiry, _ = _client.jwt_grant(
                              ^^^^^^^^^^^^^^^^^^
  File "/home/chon/project/env/lib/python3.11/site-packages/google/oauth2/_client.py", line 299, in jwt_grant
    response_data = _token_endpoint_request(
                    ^^^^^^^^^^^^^^^^^^^^^^^^
  File "/home/chon/project/env/lib/python3.11/site-packages/google/oauth2/_client.py", line 270, in _token_endpoint_request
    _handle_error_response(response_data, retryable_error)
  File "/home/chon/project/env/lib/python3.11/site-packages/google/oauth2/_client.py", line 69, in _handle_error_response
    raise exceptions.RefreshError(
google.auth.exceptions.RefreshError: ('invalid_grant: Invalid JWT Signature.', {'error': 'invalid_grant', 'error_description': 'Invalid JWT Signature.'})
2025-08-25 00:09:53,133 - ERROR - AuthMetadataPluginCallback "<google.auth.transport.grpc.AuthMetadataPlugin object at 0x7ffef9bf4fd0>" raised exception!
Traceback (most recent call last):
  File "/home/chon/project/env/lib/python3.11/site-packages/grpc/_plugin_wrapping.py", line 105, in __call__
    self._metadata_plugin(
  File "/home/chon/project/env/lib/python3.11/site-packages/google/auth/transport/grpc.py", line 95, in __call__
    callback(self._get_authorization_headers(context), None)
             ^^^^^^^^^^^^^^^^^^^^^^^^^^^^^^^^^^^^^^^^
  File "/home/chon/project/env/lib/python3.11/site-packages/google/auth/transport/grpc.py", line 81, in _get_authorization_headers
    self._credentials.before_request(
  File "/home/chon/project/env/lib/python3.11/site-packages/google/auth/credentials.py", line 239, in before_request
    self._blocking_refresh(request)
  File "/home/chon/project/env/lib/python3.11/site-packages/google/auth/credentials.py", line 202, in _blocking_refresh
    self.refresh(request)
  File "/home/chon/project/env/lib/python3.11/site-packages/google/oauth2/service_account.py", line 448, in refresh
    access_token, expiry, _ = _client.jwt_grant(
                              ^^^^^^^^^^^^^^^^^^
  File "/home/chon/project/env/lib/python3.11/site-packages/google/oauth2/_client.py", line 299, in jwt_grant
    response_data = _token_endpoint_request(
                    ^^^^^^^^^^^^^^^^^^^^^^^^
  File "/home/chon/project/env/lib/python3.11/site-packages/google/oauth2/_client.py", line 270, in _token_endpoint_request
    _handle_error_response(response_data, retryable_error)
  File "/home/chon/project/env/lib/python3.11/site-packages/google/oauth2/_client.py", line 69, in _handle_error_response
    raise exceptions.RefreshError(
google.auth.exceptions.RefreshError: ('invalid_grant: Invalid JWT Signature.', {'error': 'invalid_grant', 'error_description': 'Invalid JWT Signature.'})
2025-08-25 00:09:53,262 - ERROR - AuthMetadataPluginCallback "<google.auth.transport.grpc.AuthMetadataPlugin object at 0x7ffef9bf4fd0>" raised exception!
Traceback (most recent call last):
  File "/home/chon/project/env/lib/python3.11/site-packages/grpc/_plugin_wrapping.py", line 105, in __call__
    self._metadata_plugin(
  File "/home/chon/project/env/lib/python3.11/site-packages/google/auth/transport/grpc.py", line 95, in __call__
    callback(self._get_authorization_headers(context), None)
             ^^^^^^^^^^^^^^^^^^^^^^^^^^^^^^^^^^^^^^^^
  File "/home/chon/project/env/lib/python3.11/site-packages/google/auth/transport/grpc.py", line 81, in _get_authorization_headers
    self._credentials.before_request(
  File "/home/chon/project/env/lib/python3.11/site-packages/google/auth/credentials.py", line 239, in before_request
    self._blocking_refresh(request)
  File "/home/chon/project/env/lib/python3.11/site-packages/google/auth/credentials.py", line 202, in _blocking_refresh
    self.refresh(request)
  File "/home/chon/project/env/lib/python3.11/site-packages/google/oauth2/service_account.py", line 448, in refresh
    access_token, expiry, _ = _client.jwt_grant(
                              ^^^^^^^^^^^^^^^^^^
  File "/home/chon/project/env/lib/python3.11/site-packages/google/oauth2/_client.py", line 299, in jwt_grant
    response_data = _token_endpoint_request(
                    ^^^^^^^^^^^^^^^^^^^^^^^^
  File "/home/chon/project/env/lib/python3.11/site-packages/google/oauth2/_client.py", line 270, in _token_endpoint_request
    _handle_error_response(response_data, retryable_error)
  File "/home/chon/project/env/lib/python3.11/site-packages/google/oauth2/_client.py", line 69, in _handle_error_response
    raise exceptions.RefreshError(
google.auth.exceptions.RefreshError: ('invalid_grant: Invalid JWT Signature.', {'error': 'invalid_grant', 'error_description': 'Invalid JWT Signature.'})
2025-08-25 00:09:53,562 - ERROR - AuthMetadataPluginCallback "<google.auth.transport.grpc.AuthMetadataPlugin object at 0x7ffef9bf4fd0>" raised exception!
Traceback (most recent call last):
  File "/home/chon/project/env/lib/python3.11/site-packages/grpc/_plugin_wrapping.py", line 105, in __call__
    self._metadata_plugin(
  File "/home/chon/project/env/lib/python3.11/site-packages/google/auth/transport/grpc.py", line 95, in __call__
    callback(self._get_authorization_headers(context), None)
             ^^^^^^^^^^^^^^^^^^^^^^^^^^^^^^^^^^^^^^^^
  File "/home/chon/project/env/lib/python3.11/site-packages/google/auth/transport/grpc.py", line 81, in _get_authorization_headers
    self._credentials.before_request(
  File "/home/chon/project/env/lib/python3.11/site-packages/google/auth/credentials.py", line 239, in before_request
    self._blocking_refresh(request)
  File "/home/chon/project/env/lib/python3.11/site-packages/google/auth/credentials.py", line 202, in _blocking_refresh
    self.refresh(request)
  File "/home/chon/project/env/lib/python3.11/site-packages/google/oauth2/service_account.py", line 448, in refresh
    access_token, expiry, _ = _client.jwt_grant(
                              ^^^^^^^^^^^^^^^^^^
  File "/home/chon/project/env/lib/python3.11/site-packages/google/oauth2/_client.py", line 299, in jwt_grant
    response_data = _token_endpoint_request(
                    ^^^^^^^^^^^^^^^^^^^^^^^^
  File "/home/chon/project/env/lib/python3.11/site-packages/google/oauth2/_client.py", line 270, in _token_endpoint_request
    _handle_error_response(response_data, retryable_error)
  File "/home/chon/project/env/lib/python3.11/site-packages/google/oauth2/_client.py", line 69, in _handle_error_response
    raise exceptions.RefreshError(
google.auth.exceptions.RefreshError: ('invalid_grant: Invalid JWT Signature.', {'error': 'invalid_grant', 'error_description': 'Invalid JWT Signature.'})
2025-08-25 00:09:53,782 - ERROR - AuthMetadataPluginCallback "<google.auth.transport.grpc.AuthMetadataPlugin object at 0x7ffef9bf4fd0>" raised exception!
Traceback (most recent call last):
  File "/home/chon/project/env/lib/python3.11/site-packages/grpc/_plugin_wrapping.py", line 105, in __call__
    self._metadata_plugin(
  File "/home/chon/project/env/lib/python3.11/site-packages/google/auth/transport/grpc.py", line 95, in __call__
    callback(self._get_authorization_headers(context), None)
             ^^^^^^^^^^^^^^^^^^^^^^^^^^^^^^^^^^^^^^^^
  File "/home/chon/project/env/lib/python3.11/site-packages/google/auth/transport/grpc.py", line 81, in _get_authorization_headers
    self._credentials.before_request(
  File "/home/chon/project/env/lib/python3.11/site-packages/google/auth/credentials.py", line 239, in before_request
    self._blocking_refresh(request)
  File "/home/chon/project/env/lib/python3.11/site-packages/google/auth/credentials.py", line 202, in _blocking_refresh
    self.refresh(request)
  File "/home/chon/project/env/lib/python3.11/site-packages/google/oauth2/service_account.py", line 448, in refresh
    access_token, expiry, _ = _client.jwt_grant(
                              ^^^^^^^^^^^^^^^^^^
  File "/home/chon/project/env/lib/python3.11/site-packages/google/oauth2/_client.py", line 299, in jwt_grant
    response_data = _token_endpoint_request(
                    ^^^^^^^^^^^^^^^^^^^^^^^^
  File "/home/chon/project/env/lib/python3.11/site-packages/google/oauth2/_client.py", line 270, in _token_endpoint_request
    _handle_error_response(response_data, retryable_error)
  File "/home/chon/project/env/lib/python3.11/site-packages/google/oauth2/_client.py", line 69, in _handle_error_response
    raise exceptions.RefreshError(
google.auth.exceptions.RefreshError: ('invalid_grant: Invalid JWT Signature.', {'error': 'invalid_grant', 'error_description': 'Invalid JWT Signature.'})
2025-08-25 00:09:55,096 - ERROR - AuthMetadataPluginCallback "<google.auth.transport.grpc.AuthMetadataPlugin object at 0x7ffef9bf4fd0>" raised exception!
Traceback (most recent call last):
  File "/home/chon/project/env/lib/python3.11/site-packages/grpc/_plugin_wrapping.py", line 105, in __call__
    self._metadata_plugin(
  File "/home/chon/project/env/lib/python3.11/site-packages/google/auth/transport/grpc.py", line 95, in __call__
    callback(self._get_authorization_headers(context), None)
             ^^^^^^^^^^^^^^^^^^^^^^^^^^^^^^^^^^^^^^^^
  File "/home/chon/project/env/lib/python3.11/site-packages/google/auth/transport/grpc.py", line 81, in _get_authorization_headers
    self._credentials.before_request(
  File "/home/chon/project/env/lib/python3.11/site-packages/google/auth/credentials.py", line 239, in before_request
    self._blocking_refresh(request)
  File "/home/chon/project/env/lib/python3.11/site-packages/google/auth/credentials.py", line 202, in _blocking_refresh
    self.refresh(request)
  File "/home/chon/project/env/lib/python3.11/site-packages/google/oauth2/service_account.py", line 448, in refresh
    access_token, expiry, _ = _client.jwt_grant(
                              ^^^^^^^^^^^^^^^^^^
  File "/home/chon/project/env/lib/python3.11/site-packages/google/oauth2/_client.py", line 299, in jwt_grant
    response_data = _token_endpoint_request(
                    ^^^^^^^^^^^^^^^^^^^^^^^^
  File "/home/chon/project/env/lib/python3.11/site-packages/google/oauth2/_client.py", line 270, in _token_endpoint_request
    _handle_error_response(response_data, retryable_error)
  File "/home/chon/project/env/lib/python3.11/site-packages/google/oauth2/_client.py", line 69, in _handle_error_response
    raise exceptions.RefreshError(
google.auth.exceptions.RefreshError: ('invalid_grant: Invalid JWT Signature.', {'error': 'invalid_grant', 'error_description': 'Invalid JWT Signature.'})
2025-08-25 00:09:55,626 - ERROR - AuthMetadataPluginCallback "<google.auth.transport.grpc.AuthMetadataPlugin object at 0x7ffef9bf4fd0>" raised exception!
Traceback (most recent call last):
  File "/home/chon/project/env/lib/python3.11/site-packages/grpc/_plugin_wrapping.py", line 105, in __call__
    self._metadata_plugin(
  File "/home/chon/project/env/lib/python3.11/site-packages/google/auth/transport/grpc.py", line 95, in __call__
    callback(self._get_authorization_headers(context), None)
             ^^^^^^^^^^^^^^^^^^^^^^^^^^^^^^^^^^^^^^^^
  File "/home/chon/project/env/lib/python3.11/site-packages/google/auth/transport/grpc.py", line 81, in _get_authorization_headers
    self._credentials.before_request(
  File "/home/chon/project/env/lib/python3.11/site-packages/google/auth/credentials.py", line 239, in before_request
    self._blocking_refresh(request)
  File "/home/chon/project/env/lib/python3.11/site-packages/google/auth/credentials.py", line 202, in _blocking_refresh
    self.refresh(request)
  File "/home/chon/project/env/lib/python3.11/site-packages/google/oauth2/service_account.py", line 448, in refresh
    access_token, expiry, _ = _client.jwt_grant(
                              ^^^^^^^^^^^^^^^^^^
  File "/home/chon/project/env/lib/python3.11/site-packages/google/oauth2/_client.py", line 299, in jwt_grant
    response_data = _token_endpoint_request(
                    ^^^^^^^^^^^^^^^^^^^^^^^^
  File "/home/chon/project/env/lib/python3.11/site-packages/google/oauth2/_client.py", line 270, in _token_endpoint_request
    _handle_error_response(response_data, retryable_error)
  File "/home/chon/project/env/lib/python3.11/site-packages/google/oauth2/_client.py", line 69, in _handle_error_response
    raise exceptions.RefreshError(
google.auth.exceptions.RefreshError: ('invalid_grant: Invalid JWT Signature.', {'error': 'invalid_grant', 'error_description': 'Invalid JWT Signature.'})
2025-08-25 00:09:55,728 - ERROR - AuthMetadataPluginCallback "<google.auth.transport.grpc.AuthMetadataPlugin object at 0x7ffef9bf4fd0>" raised exception!
Traceback (most recent call last):
  File "/home/chon/project/env/lib/python3.11/site-packages/grpc/_plugin_wrapping.py", line 105, in __call__
    self._metadata_plugin(
  File "/home/chon/project/env/lib/python3.11/site-packages/google/auth/transport/grpc.py", line 95, in __call__
    callback(self._get_authorization_headers(context), None)
             ^^^^^^^^^^^^^^^^^^^^^^^^^^^^^^^^^^^^^^^^
  File "/home/chon/project/env/lib/python3.11/site-packages/google/auth/transport/grpc.py", line 81, in _get_authorization_headers
    self._credentials.before_request(
  File "/home/chon/project/env/lib/python3.11/site-packages/google/auth/credentials.py", line 239, in before_request
    self._blocking_refresh(request)
  File "/home/chon/project/env/lib/python3.11/site-packages/google/auth/credentials.py", line 202, in _blocking_refresh
    self.refresh(request)
  File "/home/chon/project/env/lib/python3.11/site-packages/google/oauth2/service_account.py", line 448, in refresh
    access_token, expiry, _ = _client.jwt_grant(
                              ^^^^^^^^^^^^^^^^^^
  File "/home/chon/project/env/lib/python3.11/site-packages/google/oauth2/_client.py", line 299, in jwt_grant
    response_data = _token_endpoint_request(
                    ^^^^^^^^^^^^^^^^^^^^^^^^
  File "/home/chon/project/env/lib/python3.11/site-packages/google/oauth2/_client.py", line 270, in _token_endpoint_request
    _handle_error_response(response_data, retryable_error)
  File "/home/chon/project/env/lib/python3.11/site-packages/google/oauth2/_client.py", line 69, in _handle_error_response
    raise exceptions.RefreshError(
google.auth.exceptions.RefreshError: ('invalid_grant: Invalid JWT Signature.', {'error': 'invalid_grant', 'error_description': 'Invalid JWT Signature.'})
2025-08-25 00:09:56,178 - ERROR - AuthMetadataPluginCallback "<google.auth.transport.grpc.AuthMetadataPlugin object at 0x7ffef9bf4fd0>" raised exception!
Traceback (most recent call last):
  File "/home/chon/project/env/lib/python3.11/site-packages/grpc/_plugin_wrapping.py", line 105, in __call__
    self._metadata_plugin(
  File "/home/chon/project/env/lib/python3.11/site-packages/google/auth/transport/grpc.py", line 95, in __call__
    callback(self._get_authorization_headers(context), None)
             ^^^^^^^^^^^^^^^^^^^^^^^^^^^^^^^^^^^^^^^^
  File "/home/chon/project/env/lib/python3.11/site-packages/google/auth/transport/grpc.py", line 81, in _get_authorization_headers
    self._credentials.before_request(
  File "/home/chon/project/env/lib/python3.11/site-packages/google/auth/credentials.py", line 239, in before_request
    self._blocking_refresh(request)
  File "/home/chon/project/env/lib/python3.11/site-packages/google/auth/credentials.py", line 202, in _blocking_refresh
    self.refresh(request)
  File "/home/chon/project/env/lib/python3.11/site-packages/google/oauth2/service_account.py", line 448, in refresh
    access_token, expiry, _ = _client.jwt_grant(
                              ^^^^^^^^^^^^^^^^^^
  File "/home/chon/project/env/lib/python3.11/site-packages/google/oauth2/_client.py", line 299, in jwt_grant
    response_data = _token_endpoint_request(
                    ^^^^^^^^^^^^^^^^^^^^^^^^
  File "/home/chon/project/env/lib/python3.11/site-packages/google/oauth2/_client.py", line 270, in _token_endpoint_request
    _handle_error_response(response_data, retryable_error)
  File "/home/chon/project/env/lib/python3.11/site-packages/google/oauth2/_client.py", line 69, in _handle_error_response
    raise exceptions.RefreshError(
google.auth.exceptions.RefreshError: ('invalid_grant: Invalid JWT Signature.', {'error': 'invalid_grant', 'error_description': 'Invalid JWT Signature.'})
2025-08-25 00:09:57,232 - ERROR - AuthMetadataPluginCallback "<google.auth.transport.grpc.AuthMetadataPlugin object at 0x7ffef9bf4fd0>" raised exception!
Traceback (most recent call last):
  File "/home/chon/project/env/lib/python3.11/site-packages/grpc/_plugin_wrapping.py", line 105, in __call__
    self._metadata_plugin(
  File "/home/chon/project/env/lib/python3.11/site-packages/google/auth/transport/grpc.py", line 95, in __call__
    callback(self._get_authorization_headers(context), None)
             ^^^^^^^^^^^^^^^^^^^^^^^^^^^^^^^^^^^^^^^^
  File "/home/chon/project/env/lib/python3.11/site-packages/google/auth/transport/grpc.py", line 81, in _get_authorization_headers
    self._credentials.before_request(
  File "/home/chon/project/env/lib/python3.11/site-packages/google/auth/credentials.py", line 239, in before_request
    self._blocking_refresh(request)
  File "/home/chon/project/env/lib/python3.11/site-packages/google/auth/credentials.py", line 202, in _blocking_refresh
    self.refresh(request)
  File "/home/chon/project/env/lib/python3.11/site-packages/google/oauth2/service_account.py", line 448, in refresh
    access_token, expiry, _ = _client.jwt_grant(
                              ^^^^^^^^^^^^^^^^^^
  File "/home/chon/project/env/lib/python3.11/site-packages/google/oauth2/_client.py", line 299, in jwt_grant
    response_data = _token_endpoint_request(
                    ^^^^^^^^^^^^^^^^^^^^^^^^
  File "/home/chon/project/env/lib/python3.11/site-packages/google/oauth2/_client.py", line 270, in _token_endpoint_request
    _handle_error_response(response_data, retryable_error)
  File "/home/chon/project/env/lib/python3.11/site-packages/google/oauth2/_client.py", line 69, in _handle_error_response
    raise exceptions.RefreshError(
google.auth.exceptions.RefreshError: ('invalid_grant: Invalid JWT Signature.', {'error': 'invalid_grant', 'error_description': 'Invalid JWT Signature.'})
2025-08-25 00:09:57,892 - ERROR - AuthMetadataPluginCallback "<google.auth.transport.grpc.AuthMetadataPlugin object at 0x7ffef9bf4fd0>" raised exception!
Traceback (most recent call last):
  File "/home/chon/project/env/lib/python3.11/site-packages/grpc/_plugin_wrapping.py", line 105, in __call__
    self._metadata_plugin(
  File "/home/chon/project/env/lib/python3.11/site-packages/google/auth/transport/grpc.py", line 95, in __call__
    callback(self._get_authorization_headers(context), None)
             ^^^^^^^^^^^^^^^^^^^^^^^^^^^^^^^^^^^^^^^^
  File "/home/chon/project/env/lib/python3.11/site-packages/google/auth/transport/grpc.py", line 81, in _get_authorization_headers
    self._credentials.before_request(
  File "/home/chon/project/env/lib/python3.11/site-packages/google/auth/credentials.py", line 239, in before_request
    self._blocking_refresh(request)
  File "/home/chon/project/env/lib/python3.11/site-packages/google/auth/credentials.py", line 202, in _blocking_refresh
    self.refresh(request)
  File "/home/chon/project/env/lib/python3.11/site-packages/google/oauth2/service_account.py", line 448, in refresh
    access_token, expiry, _ = _client.jwt_grant(
                              ^^^^^^^^^^^^^^^^^^
  File "/home/chon/project/env/lib/python3.11/site-packages/google/oauth2/_client.py", line 299, in jwt_grant
    response_data = _token_endpoint_request(
                    ^^^^^^^^^^^^^^^^^^^^^^^^
  File "/home/chon/project/env/lib/python3.11/site-packages/google/oauth2/_client.py", line 270, in _token_endpoint_request
    _handle_error_response(response_data, retryable_error)
  File "/home/chon/project/env/lib/python3.11/site-packages/google/oauth2/_client.py", line 69, in _handle_error_response
    raise exceptions.RefreshError(
google.auth.exceptions.RefreshError: ('invalid_grant: Invalid JWT Signature.', {'error': 'invalid_grant', 'error_description': 'Invalid JWT Signature.'})
2025-08-25 00:09:58,914 - ERROR - AuthMetadataPluginCallback "<google.auth.transport.grpc.AuthMetadataPlugin object at 0x7ffef9bf4fd0>" raised exception!
Traceback (most recent call last):
  File "/home/chon/project/env/lib/python3.11/site-packages/grpc/_plugin_wrapping.py", line 105, in __call__
    self._metadata_plugin(
  File "/home/chon/project/env/lib/python3.11/site-packages/google/auth/transport/grpc.py", line 95, in __call__
    callback(self._get_authorization_headers(context), None)
             ^^^^^^^^^^^^^^^^^^^^^^^^^^^^^^^^^^^^^^^^
  File "/home/chon/project/env/lib/python3.11/site-packages/google/auth/transport/grpc.py", line 81, in _get_authorization_headers
    self._credentials.before_request(
  File "/home/chon/project/env/lib/python3.11/site-packages/google/auth/credentials.py", line 239, in before_request
    self._blocking_refresh(request)
  File "/home/chon/project/env/lib/python3.11/site-packages/google/auth/credentials.py", line 202, in _blocking_refresh
    self.refresh(request)
  File "/home/chon/project/env/lib/python3.11/site-packages/google/oauth2/service_account.py", line 448, in refresh
    access_token, expiry, _ = _client.jwt_grant(
                              ^^^^^^^^^^^^^^^^^^
  File "/home/chon/project/env/lib/python3.11/site-packages/google/oauth2/_client.py", line 299, in jwt_grant
    response_data = _token_endpoint_request(
                    ^^^^^^^^^^^^^^^^^^^^^^^^
  File "/home/chon/project/env/lib/python3.11/site-packages/google/oauth2/_client.py", line 270, in _token_endpoint_request
    _handle_error_response(response_data, retryable_error)
  File "/home/chon/project/env/lib/python3.11/site-packages/google/oauth2/_client.py", line 69, in _handle_error_response
    raise exceptions.RefreshError(
google.auth.exceptions.RefreshError: ('invalid_grant: Invalid JWT Signature.', {'error': 'invalid_grant', 'error_description': 'Invalid JWT Signature.'})
2025-08-25 00:09:58,973 - ERROR - AuthMetadataPluginCallback "<google.auth.transport.grpc.AuthMetadataPlugin object at 0x7ffef9bf4fd0>" raised exception!
Traceback (most recent call last):
  File "/home/chon/project/env/lib/python3.11/site-packages/grpc/_plugin_wrapping.py", line 105, in __call__
    self._metadata_plugin(
  File "/home/chon/project/env/lib/python3.11/site-packages/google/auth/transport/grpc.py", line 95, in __call__
    callback(self._get_authorization_headers(context), None)
             ^^^^^^^^^^^^^^^^^^^^^^^^^^^^^^^^^^^^^^^^
  File "/home/chon/project/env/lib/python3.11/site-packages/google/auth/transport/grpc.py", line 81, in _get_authorization_headers
    self._credentials.before_request(
  File "/home/chon/project/env/lib/python3.11/site-packages/google/auth/credentials.py", line 239, in before_request
    self._blocking_refresh(request)
  File "/home/chon/project/env/lib/python3.11/site-packages/google/auth/credentials.py", line 202, in _blocking_refresh
    self.refresh(request)
  File "/home/chon/project/env/lib/python3.11/site-packages/google/oauth2/service_account.py", line 448, in refresh
    access_token, expiry, _ = _client.jwt_grant(
                              ^^^^^^^^^^^^^^^^^^
  File "/home/chon/project/env/lib/python3.11/site-packages/google/oauth2/_client.py", line 299, in jwt_grant
    response_data = _token_endpoint_request(
                    ^^^^^^^^^^^^^^^^^^^^^^^^
  File "/home/chon/project/env/lib/python3.11/site-packages/google/oauth2/_client.py", line 270, in _token_endpoint_request
    _handle_error_response(response_data, retryable_error)
  File "/home/chon/project/env/lib/python3.11/site-packages/google/oauth2/_client.py", line 69, in _handle_error_response
    raise exceptions.RefreshError(
google.auth.exceptions.RefreshError: ('invalid_grant: Invalid JWT Signature.', {'error': 'invalid_grant', 'error_description': 'Invalid JWT Signature.'})
2025-08-25 00:09:59,083 - ERROR - AuthMetadataPluginCallback "<google.auth.transport.grpc.AuthMetadataPlugin object at 0x7ffef9bf4fd0>" raised exception!
Traceback (most recent call last):
  File "/home/chon/project/env/lib/python3.11/site-packages/grpc/_plugin_wrapping.py", line 105, in __call__
    self._metadata_plugin(
  File "/home/chon/project/env/lib/python3.11/site-packages/google/auth/transport/grpc.py", line 95, in __call__
    callback(self._get_authorization_headers(context), None)
             ^^^^^^^^^^^^^^^^^^^^^^^^^^^^^^^^^^^^^^^^
  File "/home/chon/project/env/lib/python3.11/site-packages/google/auth/transport/grpc.py", line 81, in _get_authorization_headers
    self._credentials.before_request(
  File "/home/chon/project/env/lib/python3.11/site-packages/google/auth/credentials.py", line 239, in before_request
    self._blocking_refresh(request)
  File "/home/chon/project/env/lib/python3.11/site-packages/google/auth/credentials.py", line 202, in _blocking_refresh
    self.refresh(request)
  File "/home/chon/project/env/lib/python3.11/site-packages/google/oauth2/service_account.py", line 448, in refresh
    access_token, expiry, _ = _client.jwt_grant(
                              ^^^^^^^^^^^^^^^^^^
  File "/home/chon/project/env/lib/python3.11/site-packages/google/oauth2/_client.py", line 299, in jwt_grant
    response_data = _token_endpoint_request(
                    ^^^^^^^^^^^^^^^^^^^^^^^^
  File "/home/chon/project/env/lib/python3.11/site-packages/google/oauth2/_client.py", line 270, in _token_endpoint_request
    _handle_error_response(response_data, retryable_error)
  File "/home/chon/project/env/lib/python3.11/site-packages/google/oauth2/_client.py", line 69, in _handle_error_response
    raise exceptions.RefreshError(
google.auth.exceptions.RefreshError: ('invalid_grant: Invalid JWT Signature.', {'error': 'invalid_grant', 'error_description': 'Invalid JWT Signature.'})
2025-08-25 00:09:59,283 - ERROR - AuthMetadataPluginCallback "<google.auth.transport.grpc.AuthMetadataPlugin object at 0x7ffef9bf4fd0>" raised exception!
Traceback (most recent call last):
  File "/home/chon/project/env/lib/python3.11/site-packages/grpc/_plugin_wrapping.py", line 105, in __call__
    self._metadata_plugin(
  File "/home/chon/project/env/lib/python3.11/site-packages/google/auth/transport/grpc.py", line 95, in __call__
    callback(self._get_authorization_headers(context), None)
             ^^^^^^^^^^^^^^^^^^^^^^^^^^^^^^^^^^^^^^^^
  File "/home/chon/project/env/lib/python3.11/site-packages/google/auth/transport/grpc.py", line 81, in _get_authorization_headers
    self._credentials.before_request(
  File "/home/chon/project/env/lib/python3.11/site-packages/google/auth/credentials.py", line 239, in before_request
    self._blocking_refresh(request)
  File "/home/chon/project/env/lib/python3.11/site-packages/google/auth/credentials.py", line 202, in _blocking_refresh
    self.refresh(request)
  File "/home/chon/project/env/lib/python3.11/site-packages/google/oauth2/service_account.py", line 448, in refresh
    access_token, expiry, _ = _client.jwt_grant(
                              ^^^^^^^^^^^^^^^^^^
  File "/home/chon/project/env/lib/python3.11/site-packages/google/oauth2/_client.py", line 299, in jwt_grant
    response_data = _token_endpoint_request(
                    ^^^^^^^^^^^^^^^^^^^^^^^^
  File "/home/chon/project/env/lib/python3.11/site-packages/google/oauth2/_client.py", line 270, in _token_endpoint_request
    _handle_error_response(response_data, retryable_error)
  File "/home/chon/project/env/lib/python3.11/site-packages/google/oauth2/_client.py", line 69, in _handle_error_response
    raise exceptions.RefreshError(
google.auth.exceptions.RefreshError: ('invalid_grant: Invalid JWT Signature.', {'error': 'invalid_grant', 'error_description': 'Invalid JWT Signature.'})
2025-08-25 00:09:59,419 - ERROR - AuthMetadataPluginCallback "<google.auth.transport.grpc.AuthMetadataPlugin object at 0x7ffef9bf4fd0>" raised exception!
Traceback (most recent call last):
  File "/home/chon/project/env/lib/python3.11/site-packages/grpc/_plugin_wrapping.py", line 105, in __call__
    self._metadata_plugin(
  File "/home/chon/project/env/lib/python3.11/site-packages/google/auth/transport/grpc.py", line 95, in __call__
    callback(self._get_authorization_headers(context), None)
             ^^^^^^^^^^^^^^^^^^^^^^^^^^^^^^^^^^^^^^^^
  File "/home/chon/project/env/lib/python3.11/site-packages/google/auth/transport/grpc.py", line 81, in _get_authorization_headers
    self._credentials.before_request(
  File "/home/chon/project/env/lib/python3.11/site-packages/google/auth/credentials.py", line 239, in before_request
    self._blocking_refresh(request)
  File "/home/chon/project/env/lib/python3.11/site-packages/google/auth/credentials.py", line 202, in _blocking_refresh
    self.refresh(request)
  File "/home/chon/project/env/lib/python3.11/site-packages/google/oauth2/service_account.py", line 448, in refresh
    access_token, expiry, _ = _client.jwt_grant(
                              ^^^^^^^^^^^^^^^^^^
  File "/home/chon/project/env/lib/python3.11/site-packages/google/oauth2/_client.py", line 299, in jwt_grant
    response_data = _token_endpoint_request(
                    ^^^^^^^^^^^^^^^^^^^^^^^^
  File "/home/chon/project/env/lib/python3.11/site-packages/google/oauth2/_client.py", line 270, in _token_endpoint_request
    _handle_error_response(response_data, retryable_error)
  File "/home/chon/project/env/lib/python3.11/site-packages/google/oauth2/_client.py", line 69, in _handle_error_response
    raise exceptions.RefreshError(
google.auth.exceptions.RefreshError: ('invalid_grant: Invalid JWT Signature.', {'error': 'invalid_grant', 'error_description': 'Invalid JWT Signature.'})
2025-08-25 00:09:59,539 - ERROR - AuthMetadataPluginCallback "<google.auth.transport.grpc.AuthMetadataPlugin object at 0x7ffef9bf4fd0>" raised exception!
Traceback (most recent call last):
  File "/home/chon/project/env/lib/python3.11/site-packages/grpc/_plugin_wrapping.py", line 105, in __call__
    self._metadata_plugin(
  File "/home/chon/project/env/lib/python3.11/site-packages/google/auth/transport/grpc.py", line 95, in __call__
    callback(self._get_authorization_headers(context), None)
             ^^^^^^^^^^^^^^^^^^^^^^^^^^^^^^^^^^^^^^^^
  File "/home/chon/project/env/lib/python3.11/site-packages/google/auth/transport/grpc.py", line 81, in _get_authorization_headers
    self._credentials.before_request(
  File "/home/chon/project/env/lib/python3.11/site-packages/google/auth/credentials.py", line 239, in before_request
    self._blocking_refresh(request)
  File "/home/chon/project/env/lib/python3.11/site-packages/google/auth/credentials.py", line 202, in _blocking_refresh
    self.refresh(request)
  File "/home/chon/project/env/lib/python3.11/site-packages/google/oauth2/service_account.py", line 448, in refresh
    access_token, expiry, _ = _client.jwt_grant(
                              ^^^^^^^^^^^^^^^^^^
  File "/home/chon/project/env/lib/python3.11/site-packages/google/oauth2/_client.py", line 299, in jwt_grant
    response_data = _token_endpoint_request(
                    ^^^^^^^^^^^^^^^^^^^^^^^^
  File "/home/chon/project/env/lib/python3.11/site-packages/google/oauth2/_client.py", line 270, in _token_endpoint_request
    _handle_error_response(response_data, retryable_error)
  File "/home/chon/project/env/lib/python3.11/site-packages/google/oauth2/_client.py", line 69, in _handle_error_response
    raise exceptions.RefreshError(
google.auth.exceptions.RefreshError: ('invalid_grant: Invalid JWT Signature.', {'error': 'invalid_grant', 'error_description': 'Invalid JWT Signature.'})
2025-08-25 00:09:59,662 - ERROR - AuthMetadataPluginCallback "<google.auth.transport.grpc.AuthMetadataPlugin object at 0x7ffef9bf4fd0>" raised exception!
Traceback (most recent call last):
  File "/home/chon/project/env/lib/python3.11/site-packages/grpc/_plugin_wrapping.py", line 105, in __call__
    self._metadata_plugin(
  File "/home/chon/project/env/lib/python3.11/site-packages/google/auth/transport/grpc.py", line 95, in __call__
    callback(self._get_authorization_headers(context), None)
             ^^^^^^^^^^^^^^^^^^^^^^^^^^^^^^^^^^^^^^^^
  File "/home/chon/project/env/lib/python3.11/site-packages/google/auth/transport/grpc.py", line 81, in _get_authorization_headers
    self._credentials.before_request(
  File "/home/chon/project/env/lib/python3.11/site-packages/google/auth/credentials.py", line 239, in before_request
    self._blocking_refresh(request)
  File "/home/chon/project/env/lib/python3.11/site-packages/google/auth/credentials.py", line 202, in _blocking_refresh
    self.refresh(request)
  File "/home/chon/project/env/lib/python3.11/site-packages/google/oauth2/service_account.py", line 448, in refresh
    access_token, expiry, _ = _client.jwt_grant(
                              ^^^^^^^^^^^^^^^^^^
  File "/home/chon/project/env/lib/python3.11/site-packages/google/oauth2/_client.py", line 299, in jwt_grant
    response_data = _token_endpoint_request(
                    ^^^^^^^^^^^^^^^^^^^^^^^^
  File "/home/chon/project/env/lib/python3.11/site-packages/google/oauth2/_client.py", line 270, in _token_endpoint_request
    _handle_error_response(response_data, retryable_error)
  File "/home/chon/project/env/lib/python3.11/site-packages/google/oauth2/_client.py", line 69, in _handle_error_response
    raise exceptions.RefreshError(
google.auth.exceptions.RefreshError: ('invalid_grant: Invalid JWT Signature.', {'error': 'invalid_grant', 'error_description': 'Invalid JWT Signature.'})
2025-08-25 00:09:59,906 - ERROR - AuthMetadataPluginCallback "<google.auth.transport.grpc.AuthMetadataPlugin object at 0x7ffef9bf4fd0>" raised exception!
Traceback (most recent call last):
  File "/home/chon/project/env/lib/python3.11/site-packages/grpc/_plugin_wrapping.py", line 105, in __call__
    self._metadata_plugin(
  File "/home/chon/project/env/lib/python3.11/site-packages/google/auth/transport/grpc.py", line 95, in __call__
    callback(self._get_authorization_headers(context), None)
             ^^^^^^^^^^^^^^^^^^^^^^^^^^^^^^^^^^^^^^^^
  File "/home/chon/project/env/lib/python3.11/site-packages/google/auth/transport/grpc.py", line 81, in _get_authorization_headers
    self._credentials.before_request(
  File "/home/chon/project/env/lib/python3.11/site-packages/google/auth/credentials.py", line 239, in before_request
    self._blocking_refresh(request)
  File "/home/chon/project/env/lib/python3.11/site-packages/google/auth/credentials.py", line 202, in _blocking_refresh
    self.refresh(request)
  File "/home/chon/project/env/lib/python3.11/site-packages/google/oauth2/service_account.py", line 448, in refresh
    access_token, expiry, _ = _client.jwt_grant(
                              ^^^^^^^^^^^^^^^^^^
  File "/home/chon/project/env/lib/python3.11/site-packages/google/oauth2/_client.py", line 299, in jwt_grant
    response_data = _token_endpoint_request(
                    ^^^^^^^^^^^^^^^^^^^^^^^^
  File "/home/chon/project/env/lib/python3.11/site-packages/google/oauth2/_client.py", line 270, in _token_endpoint_request
    _handle_error_response(response_data, retryable_error)
  File "/home/chon/project/env/lib/python3.11/site-packages/google/oauth2/_client.py", line 69, in _handle_error_response
    raise exceptions.RefreshError(
google.auth.exceptions.RefreshError: ('invalid_grant: Invalid JWT Signature.', {'error': 'invalid_grant', 'error_description': 'Invalid JWT Signature.'})
2025-08-25 00:10:00,014 - ERROR - AuthMetadataPluginCallback "<google.auth.transport.grpc.AuthMetadataPlugin object at 0x7ffef9bf4fd0>" raised exception!
Traceback (most recent call last):
  File "/home/chon/project/env/lib/python3.11/site-packages/grpc/_plugin_wrapping.py", line 105, in __call__
    self._metadata_plugin(
  File "/home/chon/project/env/lib/python3.11/site-packages/google/auth/transport/grpc.py", line 95, in __call__
    callback(self._get_authorization_headers(context), None)
             ^^^^^^^^^^^^^^^^^^^^^^^^^^^^^^^^^^^^^^^^
  File "/home/chon/project/env/lib/python3.11/site-packages/google/auth/transport/grpc.py", line 81, in _get_authorization_headers
    self._credentials.before_request(
  File "/home/chon/project/env/lib/python3.11/site-packages/google/auth/credentials.py", line 239, in before_request
    self._blocking_refresh(request)
  File "/home/chon/project/env/lib/python3.11/site-packages/google/auth/credentials.py", line 202, in _blocking_refresh
    self.refresh(request)
  File "/home/chon/project/env/lib/python3.11/site-packages/google/oauth2/service_account.py", line 448, in refresh
    access_token, expiry, _ = _client.jwt_grant(
                              ^^^^^^^^^^^^^^^^^^
  File "/home/chon/project/env/lib/python3.11/site-packages/google/oauth2/_client.py", line 299, in jwt_grant
    response_data = _token_endpoint_request(
                    ^^^^^^^^^^^^^^^^^^^^^^^^
  File "/home/chon/project/env/lib/python3.11/site-packages/google/oauth2/_client.py", line 270, in _token_endpoint_request
    _handle_error_response(response_data, retryable_error)
  File "/home/chon/project/env/lib/python3.11/site-packages/google/oauth2/_client.py", line 69, in _handle_error_response
    raise exceptions.RefreshError(
google.auth.exceptions.RefreshError: ('invalid_grant: Invalid JWT Signature.', {'error': 'invalid_grant', 'error_description': 'Invalid JWT Signature.'})
2025-08-25 00:10:00,169 - ERROR - AuthMetadataPluginCallback "<google.auth.transport.grpc.AuthMetadataPlugin object at 0x7ffef9bf4fd0>" raised exception!
Traceback (most recent call last):
  File "/home/chon/project/env/lib/python3.11/site-packages/grpc/_plugin_wrapping.py", line 105, in __call__
    self._metadata_plugin(
  File "/home/chon/project/env/lib/python3.11/site-packages/google/auth/transport/grpc.py", line 95, in __call__
    callback(self._get_authorization_headers(context), None)
             ^^^^^^^^^^^^^^^^^^^^^^^^^^^^^^^^^^^^^^^^
  File "/home/chon/project/env/lib/python3.11/site-packages/google/auth/transport/grpc.py", line 81, in _get_authorization_headers
    self._credentials.before_request(
  File "/home/chon/project/env/lib/python3.11/site-packages/google/auth/credentials.py", line 239, in before_request
    self._blocking_refresh(request)
  File "/home/chon/project/env/lib/python3.11/site-packages/google/auth/credentials.py", line 202, in _blocking_refresh
    self.refresh(request)
  File "/home/chon/project/env/lib/python3.11/site-packages/google/oauth2/service_account.py", line 448, in refresh
    access_token, expiry, _ = _client.jwt_grant(
                              ^^^^^^^^^^^^^^^^^^
  File "/home/chon/project/env/lib/python3.11/site-packages/google/oauth2/_client.py", line 299, in jwt_grant
    response_data = _token_endpoint_request(
                    ^^^^^^^^^^^^^^^^^^^^^^^^
  File "/home/chon/project/env/lib/python3.11/site-packages/google/oauth2/_client.py", line 270, in _token_endpoint_request
    _handle_error_response(response_data, retryable_error)
  File "/home/chon/project/env/lib/python3.11/site-packages/google/oauth2/_client.py", line 69, in _handle_error_response
    raise exceptions.RefreshError(
google.auth.exceptions.RefreshError: ('invalid_grant: Invalid JWT Signature.', {'error': 'invalid_grant', 'error_description': 'Invalid JWT Signature.'})
2025-08-25 00:56:50,397 - INFO - RTDB sink enabled (root='/pm_readings', batch=50, flush=30s)
2025-08-25 00:56:50,397 - INFO - Program started.
2025-08-25 00:57:20,973 - INFO - RTDB flush OK (7 rows)
2025-08-25 00:57:51,060 - INFO - RTDB flush OK (6 rows)
2025-08-25 00:58:21,147 - INFO - RTDB flush OK (6 rows)
2025-08-25 00:58:51,229 - INFO - RTDB flush OK (6 rows)
2025-08-25 00:58:51,987 - INFO - RTDB flush OK (1 rows)
2025-08-25 00:58:51,987 - INFO - Cleanup done.
2025-08-25 17:01:59,754 - ERROR - RTDB init failed; CSV-only. [Errno 2] No such file or directory: '/home/chon/project/firebase-adminsdk.json'
2025-08-25 17:01:59,755 - INFO - Program started.
2025-08-25 17:03:06,207 - INFO - Cleanup done.
2025-08-25 17:06:10,385 - INFO - RTDB sink enabled (root='/pm_readings', batch=50, flush=30s)
2025-08-25 17:06:10,385 - INFO - Program started.
2025-08-25 17:06:41,045 - INFO - RTDB flush OK (7 rows)
2025-08-25 17:07:11,120 - INFO - RTDB flush OK (6 rows)
2025-08-25 17:07:41,202 - INFO - RTDB flush OK (6 rows)
2025-08-25 17:08:11,291 - INFO - RTDB flush OK (6 rows)
2025-08-25 17:08:41,371 - INFO - RTDB flush OK (6 rows)
2025-08-25 17:09:11,460 - INFO - RTDB flush OK (6 rows)
2025-08-25 17:09:41,546 - INFO - RTDB flush OK (6 rows)
2025-08-25 17:10:11,641 - INFO - RTDB flush OK (6 rows)
2025-08-25 17:10:41,731 - INFO - RTDB flush OK (6 rows)
2025-08-25 17:11:11,811 - INFO - RTDB flush OK (6 rows)
2025-08-25 17:11:41,891 - INFO - RTDB flush OK (6 rows)
2025-08-25 17:12:11,977 - INFO - RTDB flush OK (6 rows)
2025-08-25 17:12:42,067 - INFO - RTDB flush OK (6 rows)
2025-08-25 17:13:12,145 - INFO - RTDB flush OK (6 rows)
2025-08-25 17:13:42,233 - INFO - RTDB flush OK (6 rows)
2025-08-25 17:14:05,009 - INFO - RTDB flush OK (5 rows)
2025-08-25 17:14:05,009 - INFO - Cleanup done.
